Workbook

Sheet hepatitis
A1: age | B1: sex | C1: steroid | D1: antivirals | E1: fatigue | F1: malaise | G1: anorexia | H1: liver_big | I1: liver_firm | J1: spleen_palpable | K1: spiders | L1: ascites | M1: varices | N1: bilirubin | O1: alk_phosphate | P1: sgot | Q1: albumin | R1: protime | S1: histology | T1: class
A2: 30 | B2: male | C2: false | D2: false | E2: false | F2: false | G2: false | H2: false | I2: false | J2: false | K2: false | L2: false | M2: false | N2: 1 | O2: 85 | P2: 18 | Q2: 4 | S2: false | T2: live
A3: 50 | B3: female | C3: false | D3: false | E3: true | F3: false | G3: false | H3: false | I3: false | J3: false | K3: false | L3: false | M3: false | N3: 0.9 | O3: 135 | P3: 42 | Q3: 3.5 | S3: false | T3: live
A4: 78 | B4: female | C4: true | D4: false | E4: true | F4: false | G4: false | H4: true | I4: false | J4: false | K4: false | L4: false | M4: false | N4: 0.7 | O4: 96 | P4: 32 | Q4: 4 | S4: false | T4: live
A5: 31 | B5: female | D5: true | E5: false | F5: false | G5: false | H5: true | I5: false | J5: false | K5: false | L5: false | M5: false | N5: 0.7 | O5: 46 | P5: 52 | Q5: 4 | R5: 80 | S5: false | T5: live
A6: 34 | B6: female | C6: true | D6: false | E6: false | F6: false | G6: false | H6: true | I6: false | J6: false | K6: false | L6: false | M6: false | N6: 1 | P6: 200 | Q6: 4 | S6: false | T6: live
A7: 34 | B7: female | C7: true | D7: false | E7: false | F7: false | G7: false | H7: true | I7: false | J7: false | K7: false | L7: false | M7: false | N7: 0.9 | O7: 95 | P7: 28 | Q7: 4 | R7: 75 | S7: false | T7: live
A8: 51 | B8: female | C8: false | D8: false | E8: true | F8: false | G8: true | H8: true | I8: false | J8: true | K8: true | L8: false | M8: false | S8: false | T8: die
A9: 23 | B9: female | C9: true | D9: false | E9: false | F9: false | G9: false | H9: true | I9: false | J9: false | K9: false | L9: false | M9: false | N9: 1 | S9: false | T9: live
A10: 39 | B10: female | C10: true | D10: false | E10: true | F10: false | G10: false | H10: true | I10: true | J10: false | K10: false | L10: false | M10: false | N10: 0.7 | P10: 48 | Q10: 4.4 | S10: false | T10: live
A11: 30 | B11: female | C11: true | D11: false | E11: false | F11: false | G11: false | H11: true | I11: false | J11: false | K11: false | L11: false | M11: false | N11: 1 | P11: 120 | Q11: 3.9 | S11: false | T11: live
A12: 39 | B12: female | C12: false | D12: true | E12: false | F12: false | G12: false | H12: false | I12: true | J12: false | K12: false | L12: false | M12: false | N12: 1.3 | O12: 78 | P12: 30 | Q12: 4.4 | R12: 85 | S12: false | T12: live
A13: 32 | B13: female | C13: true | D13: true | E13: true | F13: false | G13: false | H13: true | I13: true | J13: false | K13: true | L13: false | M13: false | N13: 1 | O13: 59 | P13: 249 | Q13: 3.7 | R13: 54 | S13: false | T13: live
A14: 41 | B14: female | C14: true | D14: true | E14: true | F14: false | G14: false | H14: true | I14: true | J14: false | K14: false | L14: false | M14: false | N14: 0.9 | O14: 81 | P14: 60 | Q14: 3.9 | R14: 52 | S14: false | T14: live
A15: 30 | B15: female | C15: true | D15: false | E15: true | F15: false | G15: false | H15: true | I15: true | J15: false | K15: false | L15: false | M15: false | N15: 2.2 | O15: 57 | P15: 144 | Q15: 4.9 | R15: 78 | S15: false | T15: live
A16: 47 | B16: female | C16: false | D16: true | E16: false | F16: false | G16: false | H16: true | I16: false | J16: false | K16: false | L16: false | M16: false | P16: 60 | S16: false | T16: live
A17: 38 | B17: female | C17: false | D17: false | E17: true | F17: true | G17: true | H17: true | I17: false | J17: false | K17: false | L17: true | M17: false | N17: 2 | O17: 72 | P17: 89 | Q17: 2.9 | R17: 46 | S17: false | T17: live
A18: 66 | B18: female | C18: true | D18: false | E18: true | F18: false | G18: false | H18: true | I18: false | J18: false | K18: false | L18: false | M18: false | N18: 1.2 | O18: 102 | P18: 53 | Q18: 4.3 | S18: false | T18: live
A19: 40 | B19: female | C19: false | D19: false | E19: true | F19: false | G19: false | H19: true | I19: true | J19: false | K19: false | L19: false | M19: false | N19: 0.6 | O19: 62 | P19: 166 | Q19: 4 | R19: 63 | S19: false | T19: live
A20: 38 | B20: female | C20: true | D20: false | E20: false | F20: false | G20: false | H20: true | I20: false | J20: false | K20: false | L20: false | M20: false | N20: 0.7 | O20: 53 | P20: 42 | Q20: 4.1 | R20: 85 | S20: true | T20: live
A21: 38 | B21: female | C21: false | D21: true | E21: false | F21: false | G21: false | H21: false | I21: true | J21: false | K21: false | L21: false | M21: false | N21: 0.7 | O21: 70 | P21: 28 | Q21: 4.2 | R21: 62 | S21: false | T21: live
A22: 22 | B22: male | C22: true | D22: true | E22: true | F22: false | G22: false | H22: true | I22: false | J22: false | K22: false | L22: false | M22: false | N22: 0.9 | O22: 48 | P22: 20 | Q22: 4.2 | R22: 64 | S22: false | T22: live
A23: 27 | B23: female | C23: true | D23: false | E23: true | F23: true | G23: true | H23: false | I23: true | J23: true | K23: true | L23: false | M23: false | N23: 1.2 | O23: 133 | P23: 98 | Q23: 4.1 | R23: 39 | S23: false | T23: live
A24: 31 | B24: female | C24: true | D24: false | E24: false | F24: false | G24: false | H24: true | I24: false | J24: false | K24: false | L24: false | M24: false | N24: 1 | O24: 85 | P24: 20 | Q24: 4 | R24: 100 | S24: false | T24: live
A25: 42 | B25: female | C25: true | D25: false | E25: false | F25: false | G25: false | H25: true | I25: false | J25: false | K25: false | L25: false | M25: false | N25: 0.9 | O25: 60 | P25: 63 | Q25: 4.7 | R25: 47 | S25: false | T25: live
A26: 25 | B26: male | C26: false | D26: true | E26: false | F26: false | G26: false | H26: true | I26: false | J26: false | K26: false | L26: false | M26: false | N26: 0.4 | O26: 45 | P26: 18 | Q26: 4.3 | R26: 70 | S26: false | T26: live
A27: 27 | B27: female | C27: false | D27: false | E27: true | F27: true | G27: false | H27: true | I27: false | J27: false | K27: false | L27: false | M27: false | N27: 0.8 | O27: 95 | P27: 46 | Q27: 3.8 | R27: 100 | S27: false | T27: live
A28: 49 | B28: female | C28: false | D28: true | E28: true | F28: true | G28: true | H28: true | I28: true | J28: false | K28: true | L28: false | M28: false | N28: 0.6 | O28: 85 | P28: 48 | Q28: 3.7 | S28: false | T28: live
A29: 58 | B29: male | C29: true | D29: false | E29: true | F29: false | G29: false | H29: true | I29: true | J29: false | K29: true | L29: false | M29: false | N29: 1.4 | O29: 175 | P29: 55 | Q29: 2.7 | R29: 36 | S29: false | T29: live
A30: 61 | B30: female | C30: false | D30: false | E30: true | F30: false | G30: false | H30: false | I30: true | J30: false | K30: false | L30: false | M30: false | N30: 1.3 | O30: 78 | P30: 25 | Q30: 3.8 | R30: 100 | S30: false | T30: live
A31: 51 | B31: female | C31: false | D31: true | E31: true | F31: true | G31: false | H31: true | I31: false | J31: false | K31: false | L31: false | M31: false | N31: 1 | O31: 78 | P31: 58 | Q31: 4.6 | R31: 52 | S31: false | T31: live
A32: 39 | B32: female | C32: false | D32: true | E32: true | F32: true | G32: false | H32: true | I32: true | J32: false | K32: false | L32: false | M32: false | N32: 2.3 | O32: 280 | P32: 98 | Q32: 3.8 | R32: 40 | S32: false | T32: die
A33: 62 | B33: female | C33: false | D33: false | E33: true | F33: true | G33: false | J33: false | K33: false | L33: false | M33: false | N33: 1 | P33: 60 | S33: false | T33: die
A34: 41 | B34: male | C34: true | D34: true | E34: true | F34: true | G34: true | H34: true | I34: false | J34: false | K34: false | L34: false | M34: false | N34: 0.7 | O34: 81 | P34: 53 | Q34: 5 | R34: 74 | S34: false | T34: live
A35: 26 | B35: male | C35: false | D35: false | E35: false | F35: false | G35: false | H35: true | I35: true | J35: false | K35: false | L35: false | M35: false | N35: 0.5 | O35: 135 | P35: 29 | Q35: 3.8 | R35: 60 | S35: false | T35: live
A36: 35 | B36: female | C36: true | D36: false | E36: true | F36: false | G36: false | H36: true | I36: false | J36: false | K36: false | L36: false | M36: false | N36: 0.9 | O36: 58 | P36: 92 | Q36: 4.3 | R36: 73 | S36: false | T36: live
A37: 37 | B37: female | C37: true | D37: false | E37: true | F37: false | G37: false | H37: true | I37: false | J37: false | K37: true | L37: false | M37: false | N37: 0.6 | O37: 67 | P37: 28 | Q37: 4.2 | S37: false | T37: die
A38: 23 | B38: female | C38: true | D38: false | E38: true | F38: true | G38: true | H38: true | I38: false | J38: true | K38: false | L38: false | M38: false | N38: 1.3 | O38: 194 | P38: 150 | Q38: 4.1 | R38: 90 | S38: false | T38: live
A39: 20 | B39: male | C39: false | D39: false | E39: true | F39: true | G39: true | H39: false | I39: true | J39: true | K39: true | L39: false | M39: false | N39: 2.3 | O39: 150 | P39: 68 | Q39: 3.9 | S39: false | T39: live
A40: 42 | B40: female | C40: false | D40: false | E40: false | F40: false | G40: false | H40: true | I40: false | J40: false | K40: false | L40: false | M40: false | N40: 1 | O40: 85 | P40: 14 | Q40: 4 | R40: 100 | S40: false | T40: live
...

Sheet analysis_steps
B2: N° | C2: Date | D2: Etapes | E2: Variable(s) | F2: Action réalisée | G2: Justification | H2: Livrables | I2: Observations
D3: Téléchargement de la base et de la documentation officielle
D4: File conversion
D5: Data inspection
D6: dictionnary
D7: Descriptives statistics

Sheet data_inspection
A2: Inspection
A4: Dimensions
A6: Rows | B6: =ROWS(hepatitis!A2:A156) -> 155
A7: Columns | B7: =COLUMNS(hepatitis!A1:T1) -> 20
A9: Data quality control
A11: Duplicates | B11: 0 | C11: There is no informations in the official documentation concerning duplicates values
A13: Missing values
A15: Variables | B15: Missing values | C15: Percentage (%)
A16: Class | B16: =COUNTBLANK(hepatitis!T2:T156) -> 0 | C16: =B16/100 -> 0
A17: Age | B17: =COUNTBLANK(hepatitis!A2:A156) -> 0 | C17: =B17/100 -> 0
A18: Sex | B18: =COUNTBLANK(hepatitis!B2:B156) -> 0 | C18: =B18/100 -> 0
A19: Steroid | B19: =COUNTBLANK(hepatitis!C2:C156) -> 1 | C19: =B19/100 -> 0.01
A20: Antivirals | B20: =COUNTBLANK(hepatitis!D2:D156) -> 0 | C20: =B20/100 -> 0
A21: Fatigue | B21: =COUNTBLANK(hepatitis!E2:E156) -> 1 | C21: =B21/100 -> 0.01
A22: Malaise | B22: =COUNTBLANK(hepatitis!F2:F156) -> 1 | C22: =B22/100 -> 0.01
A23: Anorexia | B23: =COUNTBLANK(hepatitis!G2:G156) -> 1 | C23: =B23/100 -> 0.01
A24: Liver Big | B24: =COUNTBLANK(hepatitis!H2:H156) -> 10 | C24: =B24/100 -> 0.1
A25: Liver Firm | B25: =COUNTBLANK(hepatitis!I2:I156) -> 11 | C25: =B25/100 -> 0.11
A26: Spleen Palpable | B26: =COUNTBLANK(hepatitis!J2:J156) -> 5 | C26: =B26/100 -> 0.05
A27: Spiders | B27: =COUNTBLANK(hepatitis!K2:K156) -> 5 | C27: =B27/100 -> 0.05
A28: Ascites | B28: =COUNTBLANK(hepatitis!L2:L156) -> 5 | C28: =B28/100 -> 0.05
A29: Varices | B29: =COUNTBLANK(hepatitis!M2:M156) -> 5 | C29: =B29/100 -> 0.05
A30: Bilirubin | B30: =COUNTBLANK(hepatitis!N2:N156) -> 6 | C30: =B30/100 -> 0.06
A31: Alk Phosphate | B31: =COUNTBLANK(hepatitis!O2:O156) -> 29 | C31: =B31/100 -> 0.29
A32: SGOT | B32: =COUNTBLANK(hepatitis!P2:P156) -> 4 | C32: =B32/100 -> 0.04
A33: Albumin | B33: =COUNTBLANK(hepatitis!Q2:Q156) -> 16 | C33: =B33/100 -> 0.16
A34: Protime | B34: =COUNTBLANK(hepatitis!S2:S156) -> 0 | C34: =B34/100 -> 0
A35: Histology | B35: =COUNTBLANK(hepatitis!S2:S156) -> 0 | C35: =B35/100 -> 0
A38: Consistency
A40: Inconsistent data | B40: 0
A41: Inconsistent modalities | B41: 0
A44: Conclusion
A48: Control Check | B48: Result
A49: Dataset structure | B49: Consistent with the original dataset
A50: Number of observations | B50: 155
A51: Number of variables | B51: 20
A52: Duplicate records | B52: None identified
A53: Missing values | B53: Identified and quantified
A54: Inconsistent categorical values | B54: None identified
A55: Inconsistent data | B55: None identified
...

Sheet dictionnary
A3: Variables_table
A5: Variable | B5: Description | C5: Type | D5: Unit | E5: Modalities
A6: Class | B6: Patient outcome indicating if the patient died or survived | C6: Qualitative binary | E6: die; live
A7: Age | B7: Age of the patient | C7: Quantitative discrete | D7: years
A8: Sex | B8: Sex of the patient | C8: Qualitative binary | E8: male; female
A9: Steroid | B9: If the patient received steroid treatment | C9: Qualitative binary | E9: true; false
A10: Antivirals | B10: If the patient received antiviral treatment | C10: Qualitative binary | E10: true; false
A11: Fatigue | B11: Presence of fatigue | C11: Qualitative binary | E11: true; false
A12: Malaise | B12: Presence of malaise or general discomfort | C12: Qualitative binary | E12: true; false
A13: Anorexia | B13: Presence of anorexia or loss of appetite | C13: Qualitative binary | E13: true; false
A14: Liver Big | B14: Presence of an enlarged liver | C14: Qualitative binary | E14: true; false
A15: Liver Firm | B15: Presence of a firm liver | C15: Qualitative binary | E15: true; false
A16: Spleen Palpable | B16: If the spleen is palpable on physical examination | C16: Qualitative binary | E16: true; false
A17: Spiders | B17: Presence of spider nevi or spider-like blood vessels on the skin | C17: Qualitative binary | E17: true; false
A18: Ascites | B18: Presence of ascites, characterized by abnormal fluid accumulation in the abdomen | C18: Qualitative binary | E18: true; false
A19: Varices | B19: Presence of varices, which are abnormally enlarged veins associated with liver disease | C19: Qualitative binary | E19: true; false
... A25: Histology | B25: Histological examination result indicating If histological evidence of liver disease was present | C25: Qualitative binary | E25: true; false

Sheet hepatitis_table
A1: age | B1: sex | C1: steroid | D1: antivirals | E1: fatigue | F1: malaise | G1: anorexia | H1: liver_big | I1: liver_firm | J1: spleen_palpable | K1: spiders | L1: ascites | M1: varices | N1: bilirubin | O1: alk_phosphate | P1: sgot | Q1: albumin | R1: protime | S1: histology | T1: class
A2: 30 | B2: male | C2: false | D2: false | E2: false | F2: false | G2: false | H2: false | I2: false | J2: false | K2: false | L2: false | M2: false | N2: 1 | O2: 85 | P2: 18 | Q2: 4 | S2: false | T2: live
A3: 50 | B3: female | C3: false | D3: false | E3: true | F3: false | G3: false | H3: false | I3: false | J3: false | K3: false | L3: false | M3: false | N3: 0.9 | O3: 135 | P3: 42 | Q3: 3.5 | S3: false | T3: live
A4: 78 | B4: female | C4: true | D4: false | E4: true | F4: false | G4: false | H4: true | I4: false | J4: false | K4: false | L4: false | M4: false | N4: 0.7 | O4: 96 | P4: 32 | Q4: 4 | S4: false | T4: live
A5: 31 | B5: female | D5: true | E5: false | F5: false | G5: false | H5: true | I5: false | J5: false | K5: false | L5: false | M5: false | N5: 0.7 | O5: 46 | P5: 52 | Q5: 4 | R5: 80 | S5: false | T5: live
A6: 34 | B6: female | C6: true | D6: false | E6: false | F6: false | G6: false | H6: true | I6: false | J6: false | K6: false | L6: false | M6: false | N6: 1 | P6: 200 | Q6: 4 | S6: false | T6: live
A7: 34 | B7: female | C7: true | D7: false | E7: false | F7: false | G7: false | H7: true | I7: false | J7: false | K7: false | L7: false | M7: false | N7: 0.9 | O7: 95 | P7: 28 | Q7: 4 | R7: 75 | S7: false | T7: live
A8: 51 | B8: female | C8: false | D8: false | E8: true | F8: false | G8: true | H8: true | I8: false | J8: true | K8: true | L8: false | M8: false | S8: false | T8: die
A9: 23 | B9: female | C9: true | D9: false | E9: false | F9: false | G9: false | H9: true | I9: false | J9: false | K9: false | L9: false | M9: false | N9: 1 | S9: false | T9: live
A10: 39 | B10: female | C10: true | D10: false | E10: true | F10: false | G10: false | H10: true | I10: true | J10: false | K10: false | L10: false | M10: false | N10: 0.7 | P10: 48 | Q10: 4.4 | S10: false | T10: live
A11: 30 | B11: female | C11: true | D11: false | E11: false | F11: false | G11: false | H11: true | I11: false | J11: false | K11: false | L11: false | M11: false | N11: 1 | P11: 120 | Q11: 3.9 | S11: false | T11: live
A12: 39 | B12: female | C12: false | D12: true | E12: false | F12: false | G12: false | H12: false | I12: true | J12: false | K12: false | L12: false | M12: false | N12: 1.3 | O12: 78 | P12: 30 | Q12: 4.4 | R12: 85 | S12: false | T12: live
A13: 32 | B13: female | C13: true | D13: true | E13: true | F13: false | G13: false | H13: true | I13: true | J13: false | K13: true | L13: false | M13: false | N13: 1 | O13: 59 | P13: 249 | Q13: 3.7 | R13: 54 | S13: false | T13: live
A14: 41 | B14: female | C14: true | D14: true | E14: true | F14: false | G14: false | H14: true | I14: true | J14: false | K14: false | L14: false | M14: false | N14: 0.9 | O14: 81 | P14: 60 | Q14: 3.9 | R14: 52 | S14: false | T14: live
A15: 30 | B15: female | C15: true | D15: false | E15: true | F15: false | G15: false | H15: true | I15: true | J15: false | K15: false | L15: false | M15: false | N15: 2.2 | O15: 57 | P15: 144 | Q15: 4.9 | R15: 78 | S15: false | T15: live
A16: 47 | B16: female | C16: false | D16: true | E16: false | F16: false | G16: false | H16: true | I16: false | J16: false | K16: false | L16: false | M16: false | P16: 60 | S16: false | T16: live
A17: 38 | B17: female | C17: false | D17: false | E17: true | F17: true | G17: true | H17: true | I17: false | J17: false | K17: false | L17: true | M17: false | N17: 2 | O17: 72 | P17: 89 | Q17: 2.9 | R17: 46 | S17: false | T17: live
A18: 66 | B18: female | C18: true | D18: false | E18: true | F18: false | G18: false | H18: true | I18: false | J18: false | K18: false | L18: false | M18: false | N18: 1.2 | O18: 102 | P18: 53 | Q18: 4.3 | S18: false | T18: live
A19: 40 | B19: female | C19: false | D19: false | E19: true | F19: false | G19: false | H19: true | I19: true | J19: false | K19: false | L19: false | M19: false | N19: 0.6 | O19: 62 | P19: 166 | Q19: 4 | R19: 63 | S19: false | T19: live
A20: 38 | B20: female | C20: true | D20: false | E20: false | F20: false | G20: false | H20: true | I20: false | J20: false | K20: false | L20: false | M20: false | N20: 0.7 | O20: 53 | P20: 42 | Q20: 4.1 | R20: 85 | S20: true | T20: live
A21: 38 | B21: female | C21: false | D21: true | E21: false | F21: false | G21: false | H21: false | I21: true | J21: false | K21: false | L21: false | M21: false | N21: 0.7 | O21: 70 | P21: 28 | Q21: 4.2 | R21: 62 | S21: false | T21: live
A22: 22 | B22: male | C22: true | D22: true | E22: true | F22: false | G22: false | H22: true | I22: false | J22: false | K22: false | L22: false | M22: false | N22: 0.9 | O22: 48 | P22: 20 | Q22: 4.2 | R22: 64 | S22: false | T22: live
A23: 27 | B23: female | C23: true | D23: false | E23: true | F23: true | G23: true | H23: false | I23: true | J23: true | K23: true | L23: false | M23: false | N23: 1.2 | O23: 133 | P23: 98 | Q23: 4.1 | R23: 39 | S23: false | T23: live
A24: 31 | B24: female | C24: true | D24: false | E24: false | F24: false | G24: false | H24: true | I24: false | J24: false | K24: false | L24: false | M24: false | N24: 1 | O24: 85 | P24: 20 | Q24: 4 | R24: 100 | S24: false | T24: live
A25: 42 | B25: female | C25: true | D25: false | E25: false | F25: false | G25: false | H25: true | I25: false | J25: false | K25: false | L25: false | M25: false | N25: 0.9 | O25: 60 | P25: 63 | Q25: 4.7 | R25: 47 | S25: false | T25: live
A26: 25 | B26: male | C26: false | D26: true | E26: false | F26: false | G26: false | H26: true | I26: false | J26: false | K26: false | L26: false | M26: false | N26: 0.4 | O26: 45 | P26: 18 | Q26: 4.3 | R26: 70 | S26: false | T26: live
A27: 27 | B27: female | C27: false | D27: false | E27: true | F27: true | G27: false | H27: true | I27: false | J27: false | K27: false | L27: false | M27: false | N27: 0.8 | O27: 95 | P27: 46 | Q27: 3.8 | R27: 100 | S27: false | T27: live
A28: 49 | B28: female | C28: false | D28: true | E28: true | F28: true | G28: true | H28: true | I28: true | J28: false | K28: true | L28: false | M28: false | N28: 0.6 | O28: 85 | P28: 48 | Q28: 3.7 | S28: false | T28: live
A29: 58 | B29: male | C29: true | D29: false | E29: true | F29: false | G29: false | H29: true | I29: true | J29: false | K29: true | L29: false | M29: false | N29: 1.4 | O29: 175 | P29: 55 | Q29: 2.7 | R29: 36 | S29: false | T29: live
A30: 61 | B30: female | C30: false | D30: false | E30: true | F30: false | G30: false | H30: false | I30: true | J30: false | K30: false | L30: false | M30: false | N30: 1.3 | O30: 78 | P30: 25 | Q30: 3.8 | R30: 100 | S30: false | T30: live
A31: 51 | B31: female | C31: false | D31: true | E31: true | F31: true | G31: false | H31: true | I31: false | J31: false | K31: false | L31: false | M31: false | N31: 1 | O31: 78 | P31: 58 | Q31: 4.6 | R31: 52 | S31: false | T31: live
A32: 39 | B32: female | C32: false | D32: true | E32: true | F32: true | G32: false | H32: true | I32: true | J32: false | K32: false | L32: false | M32: false | N32: 2.3 | O32: 280 | P32: 98 | Q32: 3.8 | R32: 40 | S32: false | T32: die
A33: 62 | B33: female | C33: false | D33: false | E33: true | F33: true | G33: false | J33: false | K33: false | L33: false | M33: false | N33: 1 | P33: 60 | S33: false | T33: die
A34: 41 | B34: male | C34: true | D34: true | E34: true | F34: true | G34: true | H34: true | I34: false | J34: false | K34: false | L34: false | M34: false | N34: 0.7 | O34: 81 | P34: 53 | Q34: 5 | R34: 74 | S34: false | T34: live
A35: 26 | B35: male | C35: false | D35: false | E35: false | F35: false | G35: false | H35: true | I35: true | J35: false | K35: false | L35: false | M35: false | N35: 0.5 | O35: 135 | P35: 29 | Q35: 3.8 | R35: 60 | S35: false | T35: live
A36: 35 | B36: female | C36: true | D36: false | E36: true | F36: false | G36: false | H36: true | I36: false | J36: false | K36: false | L36: false | M36: false | N36: 0.9 | O36: 58 | P36: 92 | Q36: 4.3 | R36: 73 | S36: false | T36: live
A37: 37 | B37: female | C37: true | D37: false | E37: true | F37: false | G37: false | H37: true | I37: false | J37: false | K37: true | L37: false | M37: false | N37: 0.6 | O37: 67 | P37: 28 | Q37: 4.2 | S37: false | T37: die
A38: 23 | B38: female | C38: true | D38: false | E38: true | F38: true | G38: true | H38: true | I38: false | J38: true | K38: false | L38: false | M38: false | N38: 1.3 | O38: 194 | P38: 150 | Q38: 4.1 | R38: 90 | S38: false | T38: live
A39: 20 | B39: male | C39: false | D39: false | E39: true | F39: true | G39: true | H39: false | I39: true | J39: true | K39: true | L39: false | M39: false | N39: 2.3 | O39: 150 | P39: 68 | Q39: 3.9 | S39: false | T39: live
A40: 42 | B40: female | C40: false | D40: false | E40: false | F40: false | G40: false | H40: true | I40: false | J40: false | K40: false | L40: false | M40: false | N40: 1 | O40: 85 | P40: 14 | Q40: 4 | R40: 100 | S40: false | T40: live
...

Sheet descriptives_statistics
A4: Categotical variables
B6: class | C6: Headcount | D6: Percentage
B7: die | C7: 32 | D7: 0.20645161
B8: live | C8: 123 | D8: 0.79354839
B9: Total général | C9: 155 | D9: 1
A14: sex | B14: Headcount | C14: Percentage | E14: steroid | F14: Headcount | G14: Percentage | I14: antivirals | J14: Headcount | K14: Percentage
A15: female | B15: 139 | C15: 0.89677419 | E15: false | F15: 76 | G15: 0.49350649 | I15: false | J15: 131 | K15: 0.84516129
A16: male | B16: 16 | C16: 0.10322581 | E16: true | F16: 78 | G16: 0.50649351 | I16: true | J16: 24 | K16: 0.15483871
A17: Total général | B17: 155 | C17: 1 | E17: (vide) | G17: 0 | I17: Total général | J17: 155 | K17: 1
E18: Total général | F18: 154 | G18: 1
A22: fatigue | B22: Headcount | C22: Percentage | E22: malaise | F22: Headcount | G22: Percentage | I22: anorexia | J22: Headcount | K22: Percentage
A23: false | B23: 54 | C23: 0.35064935 | E23: false | F23: 93 | G23: 0.6038961 | I23: false | J23: 122 | K23: 0.79220779
A24: true | B24: 100 | C24: 0.64935065 | E24: true | F24: 61 | G24: 0.3961039 | I24: true | J24: 32 | K24: 0.20779221
A25: (vide) | C25: 0 | E25: (vide) | G25: 0 | I25: (vide) | K25: 0
A26: Total général | B26: 154 | C26: 1 | E26: Total général | F26: 154 | G26: 1 | I26: Total général | J26: 154 | K26: 1
A30: liver_big | B30: Nombre de liver_big | C30: Percentage | E30: liver_firm | F30: Headcount | G30: Percentage | I30: spleen_palpable | J30: Headcount | K30: Percentage
A31: false | B31: 25 | C31: 0.17241379 | E31: false | F31: 84 | G31: 0.58333333 | I31: false | J31: 120 | K31: 0.8
A32: true | B32: 120 | C32: 0.82758621 | E32: true | F32: 60 | G32: 0.41666667 | I32: true | J32: 30 | K32: 0.2
A33: (vide) | C33: 0 | E33: (vide) | G33: 0 | I33: (vide) | K33: 0
A34: Total général | B34: 145 | C34: 1 | E34: Total général | F34: 144 | G34: 1 | I34: Total général | J34: 150 | K34: 1
