Workbook
Name Class_IMC: 'Cleaned_data (Eng)'!$D$1
Name Class_IMC: 'Données nettoyées (Fr)'!$D$1

Sheet Sheet1
A1: D | B1: Gender | C1: BirthComor | D1: BMI measure | E1: BMI | F1: Vacstat | G1: Date 1 | H1: Date 2 | I1: Age | J1: Class | K1: Infected prior to vaccination | L1: Quantivac at 28 days | M1: Q 28 Result | N1: ODQ28Days | O1: NCPat28 days | P1: N28Results | Q1: Quantivacat3 months | R1: Q3 Result | S1: ODQ4months | T1: NCPat3months | U1: N3Result | V1: Quantivacat7months | W1: Q7Result | X1: ODQ7months | Y1: NCPat7months | Z1: N7Result | AA1: Time | AB1: Status | AC1: TruncatedTiter
A2: US-050 | B2: Female | C2: NA | D2: 22.8 | E2: Overweight | F2: Non Vaccinated | G2: =#N/A -> #N/A | H2: =#N/A -> #N/A | I2: 12 | J2: S1 | K2: N | L2: 0.1679 | M2: N | N2: 0.031 | O2: 0.7099 | P2: N | Q2: >120 | R2: R | S2: 0.958 | T2: 6.4746 | U2: R | V2: >120 | W2: R | X2: 0.589 | Y2: 3.3545 | Z2: R | AA2: 210 | AB2: 0
A3: US-509 | B3: M | C3: N | D3: 17 | E3: Normal Weight | F3: Non Vaccinated | G3: =#N/A -> #N/A | H3: =#N/A -> #N/A | I3: 12 | J3: S1 | K3: N | L3: 0.3747 | M3: N | N3: 0.035 | O3: 1.6594 | P3: R | Q3: >120 | R3: R | S3: 0.482 | T3: 6.2601 | U3: R | V3: >120 | W3: R | X3: 2.847 | Y3: 2.3946 | Z3: R | AA3: 210 | AB3: 0
A4: US-063 | B4: Female | C4: N | D4: 14.4 | E4: Underweight | F4: Non Vaccinated | G4: =#N/A -> #N/A | H4: =#N/A -> #N/A | I4: 12 | J4: S1 | K4: N | L4: 0.1022 | M4: N | N4: 0.037 | O4: 0.5253 | P4: N | Q4: >120 | R4: R | S4: 0.857 | T4: 0.2737 | U4: N | V4: >120 | W4: R | X4: 0.499 | Y4: 0.1885 | Z4: N | AA4: 210 | AB4: 0
A5: US-188 | B5: M | C5: NA | D5: 21.4 | E5: Normal Weight | F5: Non Vaccinated | G5: =#N/A -> #N/A | H5: =#N/A -> #N/A | I5: 15 | J5: S4 | K5: N | L5: 0.2861 | M5: N | N5: 0.038 | O5: 0.298 | P5: N | Q5: ***** | R5: * | S5: 0.737 | T5: 2.0179 | U5: R | V5: >120 | W5: R | X5: 0.43 | Y5: 0.6488 | Z5: N | AA5: 210 | AB5: 0
A6: US-286 | B6: M | C6: NA | D6: 33.2 | E6: Obese | F6: Non Vaccinated | G6: =#N/A -> #N/A | H6: =#N/A -> #N/A | I6: 15 | J6: S4 | K6: N | L6: 0.3317 | M6: N | N6: 0.038 | O6: 0.528 | P6: N | Q6: >120 | R6: R | S6: 3.392 | T6: 0.3179 | U6: N | V6: >120 | W6: R | X6: 3.2 | Y6: 0.1482 | Z6: N | AA6: 210 | AB6: 0
A7: US-116 | B7: Female | C7: Y | D7: 25.5 | E7: Overweight | F7: Non Vaccinated | G7: =#N/A -> #N/A | H7: =#N/A -> #N/A | I7: 14 | J7: S4 | K7: N | L7: 0.2117 | M7: N | N7: 0.04 | O7: 0.1868 | P7: N | Q7: 0.2649 | R7: N | S7: 0.05 | T7: 0.083 | U7: N | V7: 0.0426 | W7: N | X7: 0.031 | Y7: 0.1496 | Z7: N
A8: US-544 | B8: Female | C8: N | D8: 17.6 | E8: Normal Weight | F8: Non Vaccinated | G8: =#N/A -> #N/A | H8: =#N/A -> #N/A | I8: 12 | J8: S1 | K8: N | L8: 0.1797 | M8: N | N8: 0.041 | O8: 1.2327 | P8: R | Q8: >120 | R8: R | S8: 1.84 | T8: 0.5941 | U8: N | V8: >120 | W8: R | X8: 1.691 | Y8: 6.0625 | Z8: R | AA8: 210 | AB8: 0
A9: US-551 | B9: M | C9: NA | D9: 22.1 | E9: Overweight | F9: Non Vaccinated | G9: =#N/A -> #N/A | H9: =#N/A -> #N/A | I9: 12 | J9: S1 | K9: N | L9: 0.2709 | M9: N | N9: 0.045 | O9: 1.1834 | P9: R | Q9: >120 | R9: R | S9: 0.321 | T9: 6.1808 | U9: R | V9: ***** | W9: * | X9: 2.068 | Y9: 1.9138/1.8862 | Z9: R | AA9: 210 | AB9: 0
A10: US-231 | B10: M | C10: Y | D10: 26.3 | E10: Overweight | F10: Vaccinated | G10: 44453 | H10: 44476 | I10: 15 | J10: S4 | K10: R | L10: 4.4375 | M10: N | N10: 0.045 | O10: 1.1459 | P10: N | Q10: >120 | R10: R | S10: 3.329 | T10: 4.2489 | U10: R | V10: ***** | W10: * | X10: 2.835 | Y10: 1.7662/1.6430 | Z10: R | AA10: 210 | AB10: 0
A11: US-547 | B11: M | C11: NA | D11: 21.4 | E11: Overweight | F11: Non Vaccinated | G11: =#N/A -> #N/A | H11: =#N/A -> #N/A | I11: 12 | J11: S1 | K11: N | L11: 0.2937 | M11: N | N11: 0.046 | O11: 1.9888 | P11: R | Q11: ***** | R11: * | S11: 2.559 | T11: 7.1226 | U11: R | V11: >120 | W11: R | X11: 1.132 | Y11: 4.0134 | Z11: R | AA11: 210 | AB11: 0
A12: US-530 | B12: M | C12: N | D12: 20.1 | E12: Normal Weight | F12: Non Vaccinated | G12: =#N/A -> #N/A | H12: =#N/A -> #N/A | I12: 15 | J12: S4 | K12: N | L12: 0.665 | M12: N | N12: 0.048 | O12: 1.1387 | P12: R | Q12: ***** | R12: * | S12: 0.033 | T12: 0.9011 | U12: N | V12: >120 | W12: R | X12: 1.945 | Y12: 0.6033 | Z12: N | AA12: 210 | AB12: 0
A13: US-149 | B13: M | C13: N | D13: 18.6 | E13: Normal Weight | F13: Non Vaccinated | G13: =#N/A -> #N/A | H13: =#N/A -> #N/A | I13: 12 | J13: S1 | K13: N | L13: 0.365 | M13: N | N13: 0.052 | O13: 0.0831/0.0814 | P13: N | Q13: >120 | R13: R | S13: 3.376 | T13: 0.1192 | U13: N | V13: >120 | W13: R | X13: 2.346 | Y13: 2.2869 | Z13: R | AA13: 210 | AB13: 0
A14: US-433 | B14: Female | C14: Y | D14: 30.8 | E14: Obese | F14: Non Vaccinated | G14: =#N/A -> #N/A | H14: =#N/A -> #N/A | I14: 15 | J14: S4 | K14: N | L14: 0.7767 | M14: N | N14: 0.053 | O14: 0.537 | P14: N | Q14: >120 | R14: R | S14: 1.131 | T14: 7.0446 | U14: N | V14: >120 | W14: R | X14: 0.732 | Y14: 1.6983 | Z14: R | AA14: 210 | AB14: 0
A15: US-258 | B15: M | C15: N | D15: 17.8 | E15: Normal Weight | F15: Non Vaccinated | G15: =#N/A -> #N/A | H15: =#N/A -> #N/A | I15: 12 | J15: S1 | K15: N | L15: 0.6755 | M15: N | N15: 0.056 | O15: 0.1332 | P15: N | Q15: ***** | R15: * | S15: 0.905 | T15: 2.6568 | U15: R | V15: ***** | W15: * | X15: 3.5 | Y15: 2.3841 | Z15: R | AA15: 210 | AB15: 0
A16: US-124 | B16: Female | C16: N | D16: 16.8 | E16: Normal Weight | F16: Non Vaccinated | G16: =#N/A -> #N/A | H16: =#N/A -> #N/A | I16: 15 | J16: S4 | K16: N | L16: 0.3431 | M16: N | N16: 0.057 | O16: 0.3231 | P16: N | Q16: >120 | R16: R | S16: 0.041 | T16: 5.6358 | U16: R | V16: >120 | W16: R | X16: 0.036 | Y16: 3.0553 | Z16: R | AA16: 210 | AB16: 0
A17: US-429 | B17: Female | C17: NA | D17: 16.6 | E17: Normal Weight | F17: Non Vaccinated | G17: =#N/A -> #N/A | H17: =#N/A -> #N/A | I17: 15 | J17: S4 | K17: N | L17: 1 | M17: N | N17: 0.063 | O17: 0.736 | P17: N | Q17: >120 | R17: R | S17: 0.868 | T17: 0.3661 | U17: N | V17: >120 | W17: R | X17: 0.389 | Y17: 3.9966 | Z17: R | AA17: 210 | AB17: 0
A18: US-150 | B18: Female | C18: N | D18: 19.3 | E18: Normal Weight | F18: Non Vaccinated | G18: =#N/A -> #N/A | H18: =#N/A -> #N/A | I18: 12 | J18: S1 | K18: N | L18: 0.4307 | M18: N | N18: 0.064 | O18: 0.4397/0.4511 | P18: N | Q18: >120 | R18: R | S18: 0.128 | T18: 0.3466 | U18: N | V18: >120 | W18: R | X18: 0.146 | Y18: 4.1619 | Z18: R | AA18: 210 | AB18: 0
A19: US-493 | B19: Female | C19: NA | D19: 21.2 | E19: Normal Weight | F19: Non Vaccinated | G19: =#N/A -> #N/A | H19: =#N/A -> #N/A | I19: 12 | J19: S1 | K19: N | L19: 1.0447 | M19: N | N19: 0.065 | O19: 2.6629 | P19: R | Q19: >120 | R19: R | S19: 0.26 | T19: 5.6682 | U19: R | V19: >120 | W19: R | X19: 0.196 | Y19: 3.5558 | Z19: R | AA19: 210 | AB19: 0
A20: US-255 | B20: M | C20: NA | D20: 21.9 | E20: Overweight | F20: Non Vaccinated | G20: =#N/A -> #N/A | H20: =#N/A -> #N/A | I20: 12 | J20: S1 | K20: N | L20: 0.8702 | M20: N | N20: 0.065 | O20: 0.0699 | P20: N | Q20: 17.0308 | R20: R | S20: 0.606 | T20: 0.9958 | U20: N | V20: ***** | W20: * | X20: 0.506 | Y20: 0.524 | Z20: N | AA20: 92 | AB20: 1
A21: US-134 | B21: Female | C21: N | D21: 25.9 | E21: Overweight | F21: Non Vaccinated | G21: =#N/A -> #N/A | H21: =#N/A -> #N/A | I21: 15 | J21: S4 | K21: R | L21: 0.5182 | M21: N | N21: 0.065 | O21: 0.2593 | P21: N | Q21: >120 | R21: R | S21: 0.384 | T21: 0.1082 | U21: N | V21: ***** | W21: * | X21: 1.256 | Y21: 3.0861 | Z21: R | AA21: 210 | AB21: 0
A22: US-137 | B22: Female | C22: NA | D22: 17.1 | E22: Normal Weight | F22: Non Vaccinated | G22: =#N/A -> #N/A | H22: =#N/A -> #N/A | I22: 14 | J22: S4 | K22: N | L22: 0.6058 | M22: N | N22: 0.067 | O22: 0.3978 | P22: N | Q22: >120 | R22: R | S22: 0.403 | T22: 0.0861 | U22: N | V22: ***** | W22: * | X22: 0.479 | Y22: 1.9324 | Z22: R | AA22: 210 | AB22: 0
A23: US-229 | B23: Female | C23: N | D23: 34.2 | E23: Obese | F23: Non Vaccinated | G23: =#N/A -> #N/A | H23: =#N/A -> #N/A | I23: 11 | J23: S1 | K23: N | L23: 1.0216 | M23: N | N23: 0.072 | O23: 0.1416 | P23: N | Q23: ***** | R23: * | S23: 0.745 | T23: 1.7825 | U23: R | V23: ***** | W23: * | X23: 2.678 | Y23: 6.219 | Z23: R | AA23: 210 | AB23: 0
A24: US-573 | B24: Female | C24: N | D24: 22.3 | E24: Overweight | F24: Non Vaccinated | G24: =#N/A -> #N/A | H24: =#N/A -> #N/A | I24: 12 | J24: S1 | K24: N | L24: 0.9089 | M24: N | N24: 0.073 | O24: 1.6025 | P24: R | Q24: >120 | R24: R | S24: 0.051 | T24: 0.6138 | U24: N | V24: >120 | W24: R | X24: 0.073 | Y24: 0.25 | Z24: N | AA24: 210 | AB24: 0
A25: US-048 | B25: M | C25: N | D25: 28.6 | E25: Obese | F25: Non Vaccinated | G25: =#N/A -> #N/A | H25: =#N/A -> #N/A | I25: 15 | J25: S4 | K25: N | L25: 1.1533 | M25: N | N25: 0.074 | O25: 0.4571 | P25: N | Q25: ***** | R25: * | S25: 0.077 | T25: 1.479 | U25: R | V25: ***** | W25: * | X25: 1.246 | Y25: 1.2029 | Z25: R | AA25: 210 | AB25: 0
A26: US-066 | B26: Female | C26: N | D26: 17.2 | E26: Normal Weight | F26: Non Vaccinated | G26: =#N/A -> #N/A | H26: =#N/A -> #N/A | I26: 12 | J26: S1 | K26: N | L26: 1.1533 | M26: N | N26: 0.089 | O26: 0.2923 | P26: N | Q26: ***** | R26: * | S26: 0.684 | T26: 3.0044 | U26: R | V26: ***** | W26: * | X26: 0.365 | Y26: 1.3504 | Z26: R | AA26: 210 | AB26: 0
A27: US-169 | B27: Female | C27: N | D27: 27.2 | E27: Overweight | F27: Non Vaccinated | G27: =#N/A -> #N/A | H27: =#N/A -> #N/A | I27: 15 | J27: S4 | K27: R | L27: 1.3894 | M27: N | N27: 0.089 | O27: 0.0586 | P27: N | Q27: >120 | R27: R | S27: 3.5 | T27: 5.0045 | U27: R | V27: 60.0531 | W27: R | X27: 2.813 | Y27: 1.8802 | Z27: R
A28: US-512 | B28: M | C28: NA | D28: 16.4 | E28: Normal Weight | F28: Non Vaccinated | G28: =#N/A -> #N/A | H28: =#N/A -> #N/A | I28: 12 | J28: S1 | K28: R | L28: 1.8263 | M28: N | N28: 0.1 | O28: 3.059 | P28: R | Q28: 45.4201 | R28: R | S28: 0.207 | T28: 1.6463 | U28: R | V28: 97.9592 | W28: R | X28: 0.218 | Y28: 5.7516 | Z28: R
A29: US-004 | B29: M | C29: N | D29: 16.8 | E29: Normal Weight | F29: Non Vaccinated | G29: =#N/A -> #N/A | H29: =#N/A -> #N/A | I29: 12 | J29: S1 | K29: N | L29: 1.1752 | M29: N | N29: 0.101 | O29: 0.9143 | P29: N | Q29: ***** | R29: * | S29: 1.45 | T29: 0.5828 | U29: N | V29: >120 | W29: R | X29: 0.972 | Y29: 0.416 | Z29: N | AA29: 210 | AB29: 0
A30: US-042 | B30: Female | C30: NA | D30: 19.5 | E30: Normal Weight | F30: Non Vaccinated | G30: =#N/A -> #N/A | H30: =#N/A -> #N/A | I30: 15 | J30: S4 | K30: N | L30: 1.5474 | M30: N | N30: 0.152 | O30: 0.3495 | P30: N | Q30: ***** | R30: * | S30: 0.114 | T30: 2.0442 | U30: R | V30: ***** | W30: * | X30: 0.142 | Y30: 5.2398 | Z30: R | AA30: 210 | AB30: 0
A31: US-100 | B31: Female | C31: Y | D31: 37.7 | E31: Obese | F31: Non Vaccinated | G31: =#N/A -> #N/A | H31: =#N/A -> #N/A | I31: 15 | J31: S4 | K31: R | L31: 3.6058 | M31: N | N31: 0.2 | O31: 0.4725 | P31: N | Q31: >120 | R31: R | S31: 2.5 | T31: 0.4194 | U31: N | V31: ***** | W31: * | X31: 1.843 | Y31: 1.2684 | Z31: R | AA31: 210 | AB31: 0
A32: US-484 | B32: Female | C32: Y | D32: 20.5 | E32: Normal Weight | F32: Non Vaccinated | G32: =#N/A -> #N/A | H32: =#N/A -> #N/A | I32: 12 | J32: S1 | K32: N | L32: 4.1935 | M32: N | N32: 0.206 | O32: 1.3844 | P32: R | Q32: >120 | R32: R | S32: 0.068 | T32: 1.2466 | U32: R | V32: >120 | W32: R | X32: 0.067 | Y32: 5.7789 | Z32: R | AA32: 210 | AB32: 0
A33: US-453 | B33: Female | C33: N | D33: 18.8 | E33: Normal Weight | F33: Non Vaccinated | G33: =#N/A -> #N/A | H33: =#N/A -> #N/A | I33: 14 | J33: S4 | K33: N | L33: 4.7742 | M33: N | N33: 0.232 | O33: 1.8154 | P33: R | Q33: 48.7591 | R33: R | S33: 3.421 | T33: 1.5938 | U33: R | V33: 37.8616 | W33: R | X33: 3.397 | Y33: 0.8293 | Z33: N
A34: US-082 | B34: M | C34: N | D34: 18.4 | E34: Normal Weight | F34: Non Vaccinated | G34: =#N/A -> #N/A | H34: =#N/A -> #N/A | I34: 15 | J34: S4 | K34: N | L34: 6.0146 | M34: N | N34: 0.292 | O34: 0.2923 | P34: N | Q34: 22.6736 | R34: R | S34: 0.382 | T34: 2.8168 | U34: R | V34: 14.0227 | W34: R | X34: 1.631 | Y34: 1.1209 | Z34: R
A35: US-543 | B35: Female | C35: N | D35: 17.2 | E35: Normal Weight | F35: Non Vaccinated | G35: =#N/A -> #N/A | H35: =#N/A -> #N/A | I35: 12 | J35: S1 | K35: N | L35: 7.0608 | M35: N | N35: 0.343 | O35: 3.0045 | P35: R | Q35: ***** | R35: * | S35: 0.256 | T35: 1.8034 | U35: R | V35: ***** | W35: * | X35: 2.683 | Y35: 6.846 | Z35: R | AA35: 210 | AB35: 0
A36: US-118 | B36: Female | C36: Y | D36: 18.1 | E36: Normal Weight | F36: Non Vaccinated | G36: =#N/A -> #N/A | H36: =#N/A -> #N/A | I36: 15 | J36: S4 | K36: R | L36: 7.7226 | M36: N | N36: 0.36 | O36: 0.6769 | P36: N | Q36: 7.5745 | R36: N | S36: 0.38 | T36: 0.4415 | U36: N | V36: >120 | W36: R | X36: 3.023 | Y36: 6.5984 | Z36: R
A37: US-526 | B37: M | C37: NA | D37: 21.7 | E37: Normal Weight | F37: Non Vaccinated | G37: =#N/A -> #N/A | H37: =#N/A -> #N/A | I37: 15 | J37: S4 | K37: R | L37: 8.9727 | M37: ? | N37: 0.42 | O37: 1.2052 | P37: R | Q37: >120 | R37: R | S37: 2.78 | T37: 5.0761 | U37: R | V37: >120 | W37: R | X37: 1.221 | Y37: 2.4363 | Z37: R | AA37: 210 | AB37: 0
A38: US-440 | B38: Female | C38: N | D38: 18 | E38: Normal Weight | F38: Non Vaccinated | G38: =#N/A -> #N/A | H38: =#N/A -> #N/A | I38: 15 | J38: S4 | K38: R | L38: 9.5533 | M38: ? | N38: 0.446 | O38: 0.0909 | P38: N | Q38: >120 | R38: R | S38: 0.251 | T38: 1.308 | U38: N | V38: 34.5493 | W38: R | X38: 1.774 | Y38: 0.7414 | Z38: N
A39: US-024 | B39: M | C39: N | D39: 19.8 | E39: Normal Weight | F39: Non Vaccinated | G39: =#N/A -> #N/A | H39: =#N/A -> #N/A | I39: 12 | J39: S1 | K39: N | L39: 9.9124 | M39: ? | N39: 0.47 | O39: 0.8635/0.7942 | P39: N | Q39: >120 | R39: R | S39: 2.322 | T39: 2.8295 | U39: R | V39: >120 | W39: R | X39: 1.453 | Y39: 0.5678 | Z39: N | AA39: 210 | AB39: 0
A40: US-101 | B40: M | C40: N | D40: 21.5 | E40: Normal Weight | F40: Non Vaccinated | G40: =#N/A -> #N/A | H40: =#N/A -> #N/A | I40: 14 | J40: S4 | K40: R | L40: 9.6496 | M40: ? | N40: 0.486 | O40: 0.3275 | P40: N | Q40: >120 | R40: R | S40: 3.374 | T40: 0.1649 | U40: N | V40: ***** | W40: * | X40: 1.898 | Y40: 1.334 | Z40: R | AA40: 210 | AB40: 0
...

Sheet Inspection
A1: Items
A2: Nombre de colonnes | B2: =COLUMNS(Sheet1!A1:AC1) -> 29
A3: Nombre de lignes | B3: =ROWS(Sheet1!A2:A295) -> 294
A5: Variables | B5: Type | C5: Modalités rencontrées | D5: Cellules vides | E5: Valeurs manquantes
A6: D | B6: Standard (Texte) | C6: =COUNTA(_xlfn.UNIQUE(Sheet1!A2:A295)) -> 294 | D6: =COUNTBLANK(Sheet1!A2:A295) -> 0 | E6: =COUNTIF(Sheet1!A2:A295,"#N/A")+COUNTIF(Sheet1!A2:A295,"NA") -> 0
A7: Gender | B7: Standard (Catégorielle) | C7: =_xlfn.TEXTJOIN(", ",TRUE,_xlfn.UNIQUE(Sheet1!B2:B295)) -> Female, M | D7: =COUNTBLANK(Sheet1!B2:B295) -> 0 | E7: =COUNTIF(Sheet1!B2:B295,"#N/A")+COUNTIF(Sheet1!B2:B295,"NA") -> 0
A8: BirthComor | B8: Standard (Catégorielle) | C8: =_xlfn.TEXTJOIN(", ",TRUE,_xlfn.UNIQUE(Sheet1!C2:C295)) -> NA, N, Y | D8: =COUNTBLANK(Sheet1!C2:C295) -> 0 | E8: =COUNTIF(Sheet1!C2:C295,"#N/A")+COUNTIF(Sheet1!C2:C295,"NA") -> 107
A9: BMI measure | B9: Nombre (Numérique) | C9: =COUNTA(_xlfn.UNIQUE(Sheet1!D2:D295)) -> 149 | D9: =COUNTBLANK(Sheet1!D2:D295) -> 0 | E9: =COUNTIF(Sheet1!D2:D295,"#N/A")+COUNTIF(Sheet1!D2:D295,"NA") -> 0
A10: BMI | B10: Standard (Catégorielle) | C10: =_xlfn.TEXTJOIN(", ", TRUE, _xlfn.UNIQUE(Sheet1!E2:E295)) -> Overweight, Normal Weight, Underweight, Obese | D10: =COUNTBLANK(Sheet1!E2:E295) -> 0 | E10: =COUNTIF(Sheet1!E2:E295,"#N/A")+COUNTIF(Sheet1!E2:E295,"NA") -> 0
A11: Vacstat | B11: Standard (Texte) | C11: =_xlfn.TEXTJOIN(", ", TRUE, _xlfn.UNIQUE(Sheet1!F2:F295)) -> Non Vaccinated, Vaccinated | D11: =COUNTBLANK(Sheet1!F2:F295) -> 0 | E11: =COUNTIF(Sheet1!F2:F295,"#N/A")+COUNTIF(Sheet1!F2:F295,"NA") -> 0
A12: Date 1 | B12: Date | C12: =COUNTA(_xlfn.UNIQUE(Sheet1!G2:G295)) -> 9 | D12: =COUNTBLANK(Sheet1!G2:G295) -> 0 | E12: =COUNTIF(Sheet1!G2:G295,"#N/A")+COUNTIF(Sheet1!G2:G295,"NA") -> 66
A13: Date 2 | B13: Date | C13: =COUNTA(_xlfn.UNIQUE(Sheet1!H2:H295)) -> 12 | D13: =COUNTBLANK(Sheet1!H2:H295) -> 0 | E13: =COUNTIF(Sheet1!H2:H295,"#N/A")+COUNTIF(Sheet1!H2:H295,"NA") -> 66
A14: Age | B14: Nombre (Numérique) | C14: =COUNTA(_xlfn.UNIQUE(Sheet1!I2:I295)) -> 6 | D14: =COUNTBLANK(Sheet1!I2:I295) -> 0 | E14: =COUNTIF(Sheet1!I2:I295,"#N/A")+COUNTIF(Sheet1!I2:I295,"NA") -> 0
A15: Class | B15: Standard (Catégorielle) | C15: =_xlfn.TEXTJOIN(", ", TRUE, _xlfn.UNIQUE(Sheet1!J2:J295)) -> S1, S4 | D15: =COUNTBLANK(Sheet1!J2:J295) -> 0 | E15: =COUNTIF(Sheet1!J2:J295,"#N/A")+COUNTIF(Sheet1!J2:J295,"NA") -> 0
A16: Infected prior to vaccination | B16: Standard (Catégorielle) | C16: =_xlfn.TEXTJOIN(", ", TRUE, _xlfn.UNIQUE(Sheet1!K2:K295)) -> N, R | D16: =COUNTBLANK(Sheet1!K2:K295) -> 0 | E16: =COUNTIF(Sheet1!K2:K295,"#N/A")+COUNTIF(Sheet1!K2:K295,"NA") -> 0
A17: Quantivac at 28 days | B17: Nombre (Numérique) | C17: =COUNTA(_xlfn.UNIQUE(Sheet1!G2:G295)) -> 9 | D17: =COUNTBLANK(Sheet1!L2:L295) -> 0 | E17: =COUNTIF(Sheet1!L2:L295,"#N/A")+COUNTIF(Sheet1!L2:L295,"NA")+COUNTIF(Sheet1!L2:L295,"*****") -> 226
A18: Q 28 Result | B18: Standard (Catégorielle) | C18: =_xlfn.TEXTJOIN(", ", TRUE, _xlfn.UNIQUE(Sheet1!M2:M295)) -> N, ?, R, * | D18: =COUNTBLANK(Sheet1!M2:M295) -> 0 | E18: =COUNTIF(Sheet1!M2:M295,"#N/A")+COUNTIF(Sheet1!M2:M295,"NA")+COUNTIF(Sheet1!L2:L295,"*")+COUNTIF(Sheet1!M2:M295,"?") -> 520
A19: ODQ28Days | B19: Nombre (Numérique) | C19: =COUNTA(_xlfn.UNIQUE(Sheet1!N2:N295)) -> 101 | D19: =COUNTBLANK(Sheet1!N2:N295) -> 0 | E19: =COUNTIF(Sheet1!N2:N295,"#N/A")+COUNTIF(Sheet1!N2:N295,"NA")+COUNTIF(Sheet1!N2:N295,"*")+COUNTIF(Sheet1!N2:N295,"?") -> 0
A20: NCPat28 days | B20: Nombre (Numérique) | C20: =COUNTA(_xlfn.UNIQUE(Sheet1!O2:O295)) -> 270 | D20: =COUNTBLANK(Sheet1!O2:O295) -> 0
A21: N28Results | B21: Standard (Catégorielle) | C21: =_xlfn.TEXTJOIN(", ", TRUE, _xlfn.UNIQUE(Sheet1!P2:P295)) -> N, R | D21: =COUNTBLANK(Sheet1!P2:P295) -> 0
A22: Quantivacat3 months | B22: Nombre (Numérique) | C22: =COUNTA(_xlfn.UNIQUE(Sheet1!Q2:Q295)) -> 49 | D22: =COUNTBLANK(Sheet1!Q2:Q295) -> 0 | E22: =COUNTIF(Sheet1!Q2:Q295,"#N/A")+COUNTIF(Sheet1!Q2:Q295,"NA")+COUNTIF(Sheet1!Q2:Q295,"*")+COUNTIF(Sheet1!Q2:Q295,"?")+COUNTIF(Sheet1!Q2:Q295,"*****") -> 494
A23: Q3 Result | B23: Standard (Catégorielle) | C23: =_xlfn.TEXTJOIN(", ", TRUE, _xlfn.UNIQUE(Sheet1!R2:R295)) -> R, *, N, ? | D23: =COUNTBLANK(Sheet1!R2:R295) -> 0 | E23: =COUNTIF(Sheet1!Q2:Q295,"*")+COUNTIF(Sheet1!Q2:Q295,"?") -> 247
A24: ODQ4months | B24: Nombre (Numérique) | C24: =COUNTA(_xlfn.UNIQUE(Sheet1!Q2:Q295)) -> 49 | D24: =COUNTBLANK(Sheet1!S2:S295) -> 0
A25: NCPat3months | B25: Nombre (Numérique) | C25: =COUNTA(_xlfn.UNIQUE(Sheet1!S2:S295)) -> 182 | D25: =COUNTBLANK(Sheet1!S2:S295) -> 0
A26: N3Result | B26: Standard (Catégorielle) | C26: =_xlfn.TEXTJOIN(", ", TRUE, _xlfn.UNIQUE(Sheet1!U2:U295)) -> R, N | D26: =COUNTBLANK(Sheet1!U2:U295) -> 0
A27: Quantivacat7months | B27: Nombre (Numérique) | C27: =COUNTA(_xlfn.UNIQUE(Sheet1!V2:V295)) -> 62 | D27: =COUNTBLANK(Sheet1!V2:V295) -> 0
A28: Q7Result | B28: Standard (Catégorielle) | C28: =_xlfn.TEXTJOIN(", ", TRUE, _xlfn.UNIQUE(Sheet1!W2:W295)) -> R, N, *, ? | D28: =COUNTBLANK(Sheet1!W2:W295) -> 0 | E28: =COUNTIF(Sheet1!W2:W295,"*")+COUNTIF(Sheet1!W2:W295,"?") -> 588
A29: ODQ7months | B29: Nombre (Numérique) | C29: =COUNTA(_xlfn.UNIQUE(Sheet1!X2:X295)) -> 209 | D29: =COUNTBLANK(Sheet1!X2:X295) -> 0
A30: NCPat7months | B30: Nombre (Numérique) | C30: =COUNTA(_xlfn.UNIQUE(Sheet1!Y2:Y295)) -> 290 | D30: =COUNTBLANK(Sheet1!Y2:Y295) -> 0
A31: N7Result | B31: Standard (Catégorielle) | C31: =_xlfn.TEXTJOIN(", ", TRUE, _xlfn.UNIQUE(Sheet1!Z2:Z295)) -> R, N | D31: =COUNTBLANK(Sheet1!Z2:Z295) -> 0
A32: Time | B32: Standard (Catégorielle) | C32: =_xlfn.TEXTJOIN(", ", TRUE, _xlfn.UNIQUE(Sheet1!AA2:AA295)) -> 210, 92, 182 | D32: =COUNTBLANK(Sheet1!AA2:AA295) -> 71
A33: Status | B33: Standard (Catégorielle) | C33: =_xlfn.TEXTJOIN(", ", TRUE, _xlfn.UNIQUE(Sheet1!AB2:AB295)) -> 0, 1 | D33: =COUNTBLANK(Sheet1!AB2:AB295) -> 71
A34: TruncatedTiter | B34: Nombre (Numérique) | C34: =COUNTA(_xlfn.UNIQUE(Sheet1!AC2:AC295)) -> 1 | D34: =COUNTBLANK(Sheet1!AC2:AC295) -> 294

Sheet Dictionnaire
A1: Dictionnaire révisé
A3: Méthode de reconstruction
A4: Hypothèses basées sur
A5: (1) L'analyse directe des valeurs,
A6: (2) Le vocabulaire standard de la sérologie vaccinale,
A7: (3) Le contexte de l'étude (adolescents scolarisés, suivi à 28j/3mois/7mois)"
A8: (4) Recherche de logique par croisement de variables
A11: Nom initial | B11: Nom proposé (FR) | C11: Nom proposé (EN) | D11: Type | E11: Signification (FR) | F11: Signification (EN) | G11: Certitude | H11: Problème identifié
A12: D | B12: ID_sujet | C12: Subject_ID | D12: Catégorique (Nominale) | E12: Identifiant unique du sujet avec préfixe "US-" | F12: Unique subject identifier with "US-" prefix | G12: Probable | H12: Signification de "US-" non confirmée
A13: Gender | B13: Sexe | C13: Sex | D13: Catégorique (Nominale) | E13: Sexe du sujet | F13: Subject's sex | G13: Certain | H13: Aucun
A14: BirthComor | B14: Comorbidite_naissance | C14: Birth_comorbidity | D14: Catégorique (Nominale) | E14: Présence de comorbidité à la naissance (Yes/No/NA) | F14: Presence of birth comorbidity (Yes/No/NA) | G14: Probable | H14: Nature exacte non précisée ; "NA" stocké comme texte
A15: BMI measure | B15: Valeur_IMC | C15: BMI_value | D15: Numérique (Décimal) | E15: Valeur numérique de l'IMC | F15: Numeric BMI value | G15: Certain | H15: Aucun
A16: BMI | B16: Classe_IMC | C16: BMI_class | D16: Catégorique (Ordinale) | E16: Catégorie de poids | F16: Weight category | G16: Certain | H16: Aucun
A17: Vacstat | B17: Statut_vaccinal | C17: Vaccination_status | D17: Catégorique (Nominale) | E17: Statut vaccinal | F17: Vaccination status | G17: Certain | H17: Aucun
A18: Date 1 | B18: Date_dose1 | C18: Dose1_date | D18: Date | E18: Date de la 1ère dose de vaccin | F18: Date of 1st vaccine dose | G18: Probable | H18: Manquants codés "#N/A" en texte
A19: Date 2 | B19: Date_dose2 | C19: Dose2_date | D19: Date | E19: Date de la 2ème dose (~3-4 sem. après) | F19: Date of 2nd dose (~3-4 weeks later) | G19: Probable | H19: Idem
A20: Age | B20: Age | C20: Age | D20: Numérique (Entier) | E20: Âge en années | F20: Age in years | G20: Certain | H20: Format "Standard"
A21: Class | B21: Classe_scolaire | C21: School_grade | D21: Catégorique (Nominale) | E21: Niveau scolaire | F21: School grade level | G21: Probable | H21: Seulement 2 modalités (S1, S4)
A22: Infected prior to vaccination | B22: Infection_anterieure | C22: Prior_infection | D22: Catégorique (Nominale) | E22: Statut sérologique avant vaccination | F22: Serological status prior to vaccination | G22: Probable | H22: "R" déduit, non documenté
... A52: TruncatedTiter | B52: Titre_tronque_dérivée | C52: Truncated_titer_derived | D52: Numérique (Continu) | E52: Titre au seuil de censure (120), rattaché au temps de suivi le plus proche | F52: Titer at censoring threshold (120), nearest follow-up time | G52: Reconstruit | H52: Colonne vide à l'origine ; construite selon règle documentée

Sheet Journal de Nettoyage
A1: N° | B1: Date | C1: Etapes | D1: Variable(s) | E1: Action réalisée | F1: Justification | G1: Livrables | H1: Observations
A2: 1 | B2: 46234 | C2: Chargement et inspection de la base | D2: Toutes les variables | E2: Inspection visuelle de la base de données, Prise de connaissances des différentes variables et leurs modalités
A3: 2 | B3: 46234 | C3: Sommaire de la base de données | D3: Toutes les variables | E3: Inspection générale de la base (Nombre de lignes et de colonnes, variables, cellules vides, valeurs manquantes)
A4: 3 | B4: 46234 | C4: Documentation | D4: Toutes les variables | E4: Construction d'un dictionnaire de données à partir de recherche sur internet et des clarifications avec l'IA | F4: Absence de documentation officielle
A5: 4 | B5: 46249 | C5: Nettoyage : Renommage des colonnes | D5: Toutes les variables | E5: Renommage des colonnes suivant le dictionnaire révisé | G5: Base de données nettoyée
A6: 5 | B6: 46249 | C6: Nettoyage : Valeurs manquantes | D6: Comorbidite_naissance, Date_Dose1, Date_Dose2 | E6: Remplacement de 107 cellules "NA" (texte) par cellules vides | F6: 100% des manquants codés en texte "NA", Aucune vraie cellule vide dans la colonne d'origine | G6: NA → (vide) | H6: Note : les "#N/A" dans Date_dose1/Date_dose2 ne sont pas du texte mais de vraies valeurs d'erreur Excel (probablement issues d'une formule =NA() ou RECHERCHEV dans le fichier source) — Rechercher/Remplacer en mode texte ne les détecte pas ; utilisation de F5 > Cellules > Erreurs à la place.
A7: 6 | B7: 46250 | C7: Nettoyage : Valeurs dupliquées | D7: CapaciteNeutralisation_(28j, 3mois, 7mois) et Titre_AC_7mois | E7: Séparation des cellules à double mesure ("xy") en 2 colonnes distinctes (_mesure1, _mesure2) via Convertir Texte en colonnes) | F7: Absence de documentation sur la nature de la 2e valeur ; choix de conserver l'information brute sans perte plutôt que de calculer une moyenne arbitraire | H7: Anomalie détectée : l'outil "Texte en colonnes" a mal interprété le séparateur décimal (confusion point virgule, paramètres régionaux français) lors de la séparation des cellules "xy" — valeurs comme "1.6594" transformées en "16594". Corrigé en spécifiant manuellement les séparateurs via le bouton "Avancé" de l'assistant. Lacolonne Titre_AC_7mois n'a pas posé de problèeme de séparateur
A8: 7 | B8: 46250 | C8: Nettoyage : Censure/codes spéciaux | D8: Titre_AC_28j, Titre_AC_3mois, Titre_AC_7mois_mesure1, Titre_AC_7mois_mesure2 | E8: Séparation de chaque colonne en 2 : "_valeur" (numérique pur) et "_statut" (Normal/Censure_haute/Echec_technique/Manquant), via SIERREUR(CNUM(...)) et test GAUCHE()/ESTVIDE(). Nous avons ">120" → valeur vide + statut "Censure_haute" ; "*****" → valeur vide + statut "Echec_technique" ; cellule vraiment vide → valeur vide + statut en cellule vide | F8: Colonnes d'origine mélangeaient valeurs numériques réelles et codes texte (">120", "*****") ; conserver l'info qualitative plutôt que de la supprimer ou d'inventer une valeur | H8: Ajout d'un test ESTVIDE() en priorité dans les formules, car les vraies cellules vides étaient mal interprétées (donnaient 0 en valeur et "Normal" en statut par défaut). CNUM() renvoie 0 sur une cellule vide au lieu d'une erreur ; nécessaire pour distinguer "vraiment manquant" de "censure"/"échec technique" ; Cellule vide : "0.00000"/"Normal" → "" / cellule vide
A9: 8 | B9: 46250 | C9: Nettoyage : Recodage catégoriel des codes spéciaux "*" et "?" | D9: Resultat_qual_28j/3mois/7mois vs Titre_AC correspondant | E9: Vérification de la cohérence entre résultat qualitatif et valeur quantitative associée ; Recodage de "*" en "Non testé" et "," en "Incertain" | F9: Validation croisée et Logique confirmée aux 3 temps : "*"↔"*****" (test non réalisé), "N"↔numérique, "R"↔(numérique ou ">120"), "?"↔numérique | 2 cas anomalies détectés ("R" associé à "*****") sur 294×3 ≈ 880 paires observées | H9: Piège rencontré : "*" et "?" sont interprétés comme caractères joker par Rechercher/Remplacer dans Excel — nécessité d'échapper avec "~*" et "~?" pour cibler les symboles littéraux.
A10: 9 | B10: 46250 | C10: Correction label | D10: Titre_AC_28j/_3mois/_7mois_mesure1/_mesure2 (statut) | E10: Remplacement global "Echec_technique" → "Non_teste" (337 cellules), puis exception manuelle sur US-111 (Titre_AC_3mois) remise en "Echec_technique" | F10: Validation croisée montrant que la quasi-totalité des cas étaient systématiques (test non réalisé) et non des pannes ; US-111 isolé et contredit le pattern
A11: 10 | B11: 46250 | C11: Correction saisie | D11: CapaciteNeutralisation_28j_mesure2 | E11: Correction de "2817" en "0.2817" (point décimal manquant, valeur aberrante comparée à mesure1=0.2817 et à la plage habituelle de la variable) ; "2817" → "0.2817" | H11: Détecté lors du scan final de vérification des caractères spéciaux résiduels
A12: 11 | B12: 46254 | C12: Standardisation catégorielle | D12: Sexe, Comorbidite_naissance, Infection_anterieure, Resultat_neutralisation_28j/3mois/7mois, Classe_IMC, Statut_vaccinal | E12: Recodage des 8 dernières colonnes catégorielles vers des libellés explicites en français (codes courts F/M/Y/N/R décodés + traduction des modalités restées en anglais) ; Ex: "F"→"Femme" ; "Overweight"→"Surpoids" ; "Vaccinated"→"Vacciné" | F12: Pour une cohérence terminologique complète du fichier | H12: Vérification exhaustive des 29 colonnes confirmant que ces 8 étaient les seules concernées (Classe_scolaire exclue, codes scolaires propres à l'étude, non traduisibles)
A13: 12 | B13: 46254 | C13: Vérification types de données | D13: Toutes les colonnes | E13: Contrôle systématique du type de chaque colonne (alignement, Ctrl+1) : colonnes numériques (Valeur_IMC, Age, Densite_optique_..., Titre_AC_..._valeur, CapaciteNeutralisation_..., Temps_suivi_jours) et colonnes dates (Date_dose1/2) vérifiées correctes ; Correction du format mixte "Standard/Nombre" sur Titre_AC_7mois_mesure_2 ; uniformisation du format des en-têtes (ligne 1) en "Standard" sur l'ensemble du fichier | H13: 2 constats sans impact réel, documentés pour mémoire : (1) en-têtes parfois au même format "Nombre" que leurs valeurs — sans effet, un en-tête reste du texte quel que soit le format appliqué ; (2) formats Standard sur Age/Temps_suivi_jours — sans impact sur les calculs. Seule vraie correction : format mixte Standard/Nombre uniformisé sur Titre_AC_7mois_mesure_2, et harmonisation des en-têtes en "Standard" ; Contrôle nécessaire après les transformations des étapes 2-4 (formules, séparations, recodages) pour s'assurer qu'aucune valeur numérique n'était restée déguisée en texte
A14: 13 | B14: 46254 | C14: Standardisation de la mise en forme | D14: Ensemble du fichier | E14: Suppression de toute la mise en forme héritée (couleurs, gras, polices, bordures manquantes) et réapplication d'un style uniforme (bordures complètes, en-têtes en gras, police unique, tableau structuré) | F14: Investigation menée avant suppression : (1) surlignage jaune sur ODQ28Days/ODQ4months coïncidant exactement avec les 2 colonnes déjà signalées comme problématiques au dictionnaire ; signal probable des auteurs originaux, confiance renforcée sur ces variables ; (2) surlignage bleu sur 2 lignes isolées (US-004, US-019) ; hypothèse de contradiction Q Result/N Results testée et rejetée : origine non déterminée, probable audit manuel des auteurs ; (3) désaccord Q Result/N Results noté comme caractéristique biologique du dataset (deux méthodes sérologiques différentes), non corrigé ; (4) cellule rouge isolée (US-116) et triangles verts Excel (BMI/Vacstat, faux-positifs standards) sans pattern confirmé. Mise en forme jugée sans valeur analytique exploitable au-delà de ces observations, supprimée après investigation
A15: 14 | B15: 46254 | C15: Construction variable dérivée | D15: Titre_tronque | E15: Colonne reconstruite (vide à l'origine) : valeur=120 si le statut de censure au temps correspondant à Temps_suivi_jours est "Censure_haute", vide sinon | F15: Absence de documentation officielle ; règle basée sur la correspondance Time/point de mesure le plus proche (92j→3mois, 182j/210j→7mois, faute de colonne dédiée à 182j) ; convention standard en analyse de survie pour encoder une censure connue
A16: 15 | B16: 46254 | C16: Indicateurs de validation | D16: Ensemble du dataset nettoyé | E16: Calcul de 6 indicateurs de vérification post-nettoyage sur feuille dédiée "Indicateurs" : (1) intégrité — 294 lignes, 294 ID uniques ; (2) répartition Censure_haute par temps (43/156/174 à 28j/3mois/7mois), conforme au croisement établi en étape 4 ; (3) progression du titre d'anticorps moyen (cas "Normal" uniquement) : 18.98 → 29.72 → 44.49, cohérente avec la logique biologique attendue (montée post-vaccinale) ; (4) cohérence chronologique Dose_Date1/Dose_Date2 (0 inversion) ; (5) plage d'âge plausible (11-16 ans) ; (6) cohérence de la variable dérivée Titre_tronque avec Statut_evenement (0 incohérence) | F16: Objectif double : produire des indicateurs de synthèse ET valider que le nettoyage des étapes 1-5 n'a pas laissé d'erreur cachée | H16: Une anomalie a été détectée par l'indicateur 3 (moyenne à 7 mois initialement à 431 321.99, hors de toute plage plausible) : facteur ×10000 résiduel sur Titre_AC_7mois_mesure_1_valeurs (bug de séparateur décimal non corrigé aux étapes précédentes, ex. US-512 : 979592→97.9592), corrigé par division ciblée des valeurs >1000

Sheet Données nettoyées (Fr)
A1: ID_sujet | B1: Sexe | C1: Comorbidite_naissance | D1: Valeur_IMC | E1: Class_IMC | F1: Statut_vaccinal | G1: Dose_Date1 | H1: Dose_Date2 | I1: Age | J1: Classe_scolaire | K1: Infection_antérieure | L1: Titre_AC_28j_statut | M1: Titre_AC_28j | N1: Titre_AC_28j_valeurs | O1: Resultat_qual_28j | P1: DensiteOptique_28j | Q1: CapaciteNeutralisation_28j_mesure1 | R1: CapaciteNeutralisation_28j_mesure2 | S1: Resultat_neutralisation_28j | T1: Titre_AC_3mois_statut | U1: Titre_AC_3mois | V1: Titre_AC_3mois_valeurs | W1: Resultat_qual_3mois | X1: DensiteOptique_3mois | Y1: CapaciteNeutralisation_3mois_mesure1 | Z1: CapaciteNeutralisation_3mois_mesure2 | AA1: Resultat_neutralisation_3mois | AB1: Titre_AC_7mois_mesure_1_statut | AC1: Titre_AC_7mois_mesure_1 | AD1: Titre_AC_7mois_mesure_1_valeurs | AE1: Titre_AC_7mois_mesure_2_statut | AF1: Titre_AC_7mois_mesure_2 | AG1: Titre_AC_7mois_mesure_2_valeurs | AH1: Resultat_qual_7mois | AI1: DensiteOptique_7mois | AJ1: CapaciteNeutralisation_7mois_mesure1 | AK1: CapaciteNeutralisation_7mois_mesure2 | AL1: Resultat_neutralisation_7mois | AM1: Temps_suivi_jours | AN1: Statut_evenement | AO1: Titre_tronque_dérivée
A2: US-050 | B2: Femme | D2: 22.8 | E2: Surpoids | F2: Non vacciné | I2: 12 | J2: S1 | K2: Négatif | L2: =IF(LEFT(M2,1)=">","Censure haute",IF(M2="*****","Non testé","Normal")) -> Normal | M2: 0.1679 | N2: =IFERROR(VALUE(M2),"") -> 0.1679 | O2: Négatif | P2: 0.031 | Q2: 0.7099 | S2: Négatif | T2: =IF(LEFT(U2,1)=">","Censure haute",IF(U2="*****","Echec technique","Normal")) -> Censure haute | U2: >120 | V2: =IFERROR(VALUE(U2),"") | W2: Réactif | X2: 0.958 | Y2: 6.4746 | AA2: Réactif | AB2: =IF(LEFT(AC2,1)=">","Censure haute",IF(AC2="*****","Non testé","Normal")) -> Censure haute | AC2: >120 | AE2: =IF(ISBLANK(AF2),"",IF(LEFT(AF2,1)=">","Censure haute",IF(AF2="*****","Non testé","Normal"))) | AG2: =IF(ISBLANK(AF2),"",IFERROR(VALUE(AF2),"")) | AH2: Réactif | AI2: 0.589 | AJ2: 3.3545 | AL2: Réactif | AM2: 210 | AN2: 0 | AO2: =IF(ISBLANK(AM2),"",IF(AM2=92,IF(T2="Censure haute",120,""),IF(AB2="Censure haute",120,""))) -> 120
A3: US-509 | B3: Homme | C3: Non | D3: 17 | E3: Poids normal | F3: Non vacciné | I3: 12 | J3: S1 | K3: Négatif | L3: =IF(LEFT(M3,1)=">","Censure haute",IF(M3="*****","Non testé","Normal")) -> Normal | M3: 0.3747 | N3: =IFERROR(VALUE(M3),"") -> 0.3747 | O3: Négatif | P3: 0.035 | Q3: 1.6594 | S3: Réactif | T3: =IF(LEFT(U3,1)=">","Censure haute",IF(U3="*****","Echec technique","Normal")) -> Censure haute | U3: >120 | V3: =IFERROR(VALUE(U3),"") | W3: Réactif | X3: 0.482 | Y3: 6.2601 | AA3: Réactif | AB3: =IF(LEFT(AC3,1)=">","Censure haute",IF(AC3="*****","Non testé","Normal")) -> Censure haute | AC3: >120 | AE3: =IF(ISBLANK(AF3),"",IF(LEFT(AF3,1)=">","Censure haute",IF(AF3="*****","Non testé","Normal"))) | AG3: =IF(ISBLANK(AF3),"",IFERROR(VALUE(AF3),"")) | AH3: Réactif | AI3: 2.847 | AJ3: 2.3946 | AL3: Réactif | AM3: 210 | AN3: 0 | AO3: =IF(ISBLANK(AM3),"",IF(AM3=92,IF(T3="Censure haute",120,""),IF(AB3="Censure haute",120,""))) -> 120
A4: US-063 | B4: Femme | C4: Non | D4: 14.4 | E4: Insuffisance pondérale | F4: Non vacciné | I4: 12 | J4: S1 | K4: Négatif | L4: =IF(LEFT(M4,1)=">","Censure haute",IF(M4="*****","Non testé","Normal")) -> Normal | M4: 0.1022 | N4: =IFERROR(VALUE(M4),"") -> 0.1022 | O4: Négatif | P4: 0.037 | Q4: 0.5253 | S4: Négatif | T4: =IF(LEFT(U4,1)=">","Censure haute",IF(U4="*****","Echec technique","Normal")) -> Censure haute | U4: >120 | V4: =IFERROR(VALUE(U4),"") | W4: Réactif | X4: 0.857 | Y4: 0.2737 | AA4: Négatif | AB4: =IF(LEFT(AC4,1)=">","Censure haute",IF(AC4="*****","Non testé","Normal")) -> Censure haute | AC4: >120 | AE4: =IF(ISBLANK(AF4),"",IF(LEFT(AF4,1)=">","Censure haute",IF(AF4="*****","Non testé","Normal"))) | AG4: =IF(ISBLANK(AF4),"",IFERROR(VALUE(AF4),"")) | AH4: Réactif | AI4: 0.499 | AJ4: 0.1885 | AL4: Négatif | AM4: 210 | AN4: 0 | AO4: =IF(ISBLANK(AM4),"",IF(AM4=92,IF(T4="Censure haute",120,""),IF(AB4="Censure haute",120,""))) -> 120
A5: US-188 | B5: Homme | D5: 21.4 | E5: Poids normal | F5: Non vacciné | I5: 15 | J5: S4 | K5: Négatif | L5: =IF(LEFT(M5,1)=">","Censure haute",IF(M5="*****","Non testé","Normal")) -> Normal | M5: 0.2861 | N5: =IFERROR(VALUE(M5),"") -> 0.2861 | O5: Négatif | P5: 0.038 | Q5: 0.298 | S5: Négatif | T5: =IF(LEFT(U5,1)=">","Censure haute",IF(U5="*****","Echec technique","Normal")) -> Echec technique | U5: ***** | V5: =IFERROR(VALUE(U5),"") | W5: Non testé | X5: 0.737 | Y5: 2.0179 | AA5: Réactif | AB5: =IF(LEFT(AC5,1)=">","Censure haute",IF(AC5="*****","Non testé","Normal")) -> Censure haute | AC5: >120 | AE5: =IF(ISBLANK(AF5),"",IF(LEFT(AF5,1)=">","Censure haute",IF(AF5="*****","Non testé","Normal"))) | AG5: =IF(ISBLANK(AF5),"",IFERROR(VALUE(AF5),"")) | AH5: Réactif | AI5: 0.43 | AJ5: 0.6488 | AL5: Négatif | AM5: 210 | AN5: 0 | AO5: =IF(ISBLANK(AM5),"",IF(AM5=92,IF(T5="Censure haute",120,""),IF(AB5="Censure haute",120,""))) -> 120
A6: US-286 | B6: Homme | D6: 33.2 | E6: Obésité | F6: Non vacciné | I6: 15 | J6: S4 | K6: Négatif | L6: =IF(LEFT(M6,1)=">","Censure haute",IF(M6="*****","Non testé","Normal")) -> Normal | M6: 0.3317 | N6: =IFERROR(VALUE(M6),"") -> 0.3317 | O6: Négatif | P6: 0.038 | Q6: 0.528 | S6: Négatif | T6: =IF(LEFT(U6,1)=">","Censure haute",IF(U6="*****","Echec technique","Normal")) -> Censure haute | U6: >120 | V6: =IFERROR(VALUE(U6),"") | W6: Réactif | X6: 3.392 | Y6: 0.3179 | AA6: Négatif | AB6: =IF(LEFT(AC6,1)=">","Censure haute",IF(AC6="*****","Non testé","Normal")) -> Censure haute | AC6: >120 | AE6: =IF(ISBLANK(AF6),"",IF(LEFT(AF6,1)=">","Censure haute",IF(AF6="*****","Non testé","Normal"))) | AG6: =IF(ISBLANK(AF6),"",IFERROR(VALUE(AF6),"")) | AH6: Réactif | AI6: 3.2 | AJ6: 0.1482 | AL6: Négatif | AM6: 210 | AN6: 0 | AO6: =IF(ISBLANK(AM6),"",IF(AM6=92,IF(T6="Censure haute",120,""),IF(AB6="Censure haute",120,""))) -> 120
A7: US-116 | B7: Femme | C7: Oui | D7: 25.5 | E7: Surpoids | F7: Non vacciné | I7: 14 | J7: S4 | K7: Négatif | L7: =IF(LEFT(M7,1)=">","Censure haute",IF(M7="*****","Non testé","Normal")) -> Normal | M7: 0.2117 | N7: =IFERROR(VALUE(M7),"") -> 0.2117 | O7: Négatif | P7: 0.04 | Q7: 0.1868 | S7: Négatif | T7: =IF(LEFT(U7,1)=">","Censure haute",IF(U7="*****","Echec technique","Normal")) -> Normal | U7: 0.2649 | V7: =IFERROR(VALUE(U7),"") -> 0.2649 | W7: Négatif | X7: 0.05 | Y7: 0.083 | AA7: Négatif | AB7: =IF(LEFT(AC7,1)=">","Censure haute",IF(AC7="*****","Non testé","Normal")) -> Normal | AC7: 0.0426 | AD7: 0.0426 | AE7: =IF(ISBLANK(AF7),"",IF(LEFT(AF7,1)=">","Censure haute",IF(AF7="*****","Non testé","Normal"))) | AG7: =IF(ISBLANK(AF7),"",IFERROR(VALUE(AF7),"")) | AH7: Négatif | AI7: 0.031 | AJ7: 0.1496 | AL7: Négatif | AO7: =IF(ISBLANK(AM7),"",IF(AM7=92,IF(T7="Censure haute",120,""),IF(AB7="Censure haute",120,"")))
A8: US-544 | B8: Femme | C8: Non | D8: 17.6 | E8: Poids normal | F8: Non vacciné | I8: 12 | J8: S1 | K8: Négatif | L8: =IF(LEFT(M8,1)=">","Censure haute",IF(M8="*****","Non testé","Normal")) -> Normal | M8: 0.1797 | N8: =IFERROR(VALUE(M8),"") -> 0.1797 | O8: Négatif | P8: 0.041 | Q8: 1.2327 | S8: Réactif | T8: =IF(LEFT(U8,1)=">","Censure haute",IF(U8="*****","Echec technique","Normal")) -> Censure haute | U8: >120 | V8: =IFERROR(VALUE(U8),"") | W8: Réactif | X8: 1.84 | Y8: 0.5941 | AA8: Négatif | AB8: =IF(LEFT(AC8,1)=">","Censure haute",IF(AC8="*****","Non testé","Normal")) -> Censure haute | AC8: >120 | AE8: =IF(ISBLANK(AF8),"",IF(LEFT(AF8,1)=">","Censure haute",IF(AF8="*****","Non testé","Normal"))) | AG8: =IF(ISBLANK(AF8),"",IFERROR(VALUE(AF8),"")) | AH8: Réactif | AI8: 1.691 | AJ8: 6.0625 | AL8: Réactif | AM8: 210 | AN8: 0 | AO8: =IF(ISBLANK(AM8),"",IF(AM8=92,IF(T8="Censure haute",120,""),IF(AB8="Censure haute",120,""))) -> 120
A9: US-551 | B9: Homme | D9: 22.1 | E9: Surpoids | F9: Non vacciné | I9: 12 | J9: S1 | K9: Négatif | L9: =IF(LEFT(M9,1)=">","Censure haute",IF(M9="*****","Non testé","Normal")) -> Normal | M9: 0.2709 | N9: =IFERROR(VALUE(M9),"") -> 0.2709 | O9: Négatif | P9: 0.045 | Q9: 1.1834 | S9: Réactif | T9: =IF(LEFT(U9,1)=">","Censure haute",IF(U9="*****","Echec technique","Normal")) -> Censure haute | U9: >120 | V9: =IFERROR(VALUE(U9),"") | W9: Réactif | X9: 0.321 | Y9: 6.1808 | AA9: Réactif | AB9: =IF(LEFT(AC9,1)=">","Censure haute",IF(AC9="*****","Non testé","Normal")) -> Non testé | AC9: ***** | AE9: =IF(ISBLANK(AF9),"",IF(LEFT(AF9,1)=">","Censure haute",IF(AF9="*****","Non testé","Normal"))) | AG9: =IF(ISBLANK(AF9),"",IFERROR(VALUE(AF9),"")) | AH9: Non testé | AI9: 2.068 | AJ9: 1.9138 | AK9: 1.8862 | AL9: Réactif | AM9: 210 | AN9: 0 | AO9: =IF(ISBLANK(AM9),"",IF(AM9=92,IF(T9="Censure haute",120,""),IF(AB9="Censure haute",120,"")))
A10: US-231 | B10: Homme | C10: Oui | D10: 26.3 | E10: Surpoids | F10: Vacciné | G10: 44453 | H10: 44476 | I10: 15 | J10: S4 | K10: Réactif | L10: =IF(LEFT(M10,1)=">","Censure haute",IF(M10="*****","Non testé","Normal")) -> Normal | M10: 4.4375 | N10: =IFERROR(VALUE(M10),"") -> 4.4375 | O10: Négatif | P10: 0.045 | Q10: 1.1459 | S10: Négatif | T10: =IF(LEFT(U10,1)=">","Censure haute",IF(U10="*****","Echec technique","Normal")) -> Censure haute | U10: >120 | V10: =IFERROR(VALUE(U10),"") | W10: Réactif | X10: 3.329 | Y10: 4.2489 | AA10: Réactif | AB10: =IF(LEFT(AC10,1)=">","Censure haute",IF(AC10="*****","Non testé","Normal")) -> Non testé | AC10: ***** | AE10: =IF(ISBLANK(AF10),"",IF(LEFT(AF10,1)=">","Censure haute",IF(AF10="*****","Non testé","Normal"))) | AG10: =IF(ISBLANK(AF10),"",IFERROR(VALUE(AF10),"")) | AH10: Non testé | AI10: 2.835 | AJ10: 1.7662 | AK10: 1.643 | AL10: Réactif | AM10: 210 | AN10: 0 | AO10: =IF(ISBLANK(AM10),"",IF(AM10=92,IF(T10="Censure haute",120,""),IF(AB10="Censure haute",120,"")))
A11: US-547 | B11: Homme | D11: 21.4 | E11: Surpoids | F11: Non vacciné | I11: 12 | J11: S1 | K11: Négatif | L11: =IF(LEFT(M11,1)=">","Censure haute",IF(M11="*****","Non testé","Normal")) -> Normal | M11: 0.2937 | N11: =IFERROR(VALUE(M11),"") -> 0.2937 | O11: Négatif | P11: 0.046 | Q11: 1.9888 | S11: Réactif | T11: =IF(LEFT(U11,1)=">","Censure haute",IF(U11="*****","Echec technique","Normal")) -> Echec technique | U11: ***** | V11: =IFERROR(VALUE(U11),"") | W11: Non testé | X11: 2.559 | Y11: 7.1226 | AA11: Réactif | AB11: =IF(LEFT(AC11,1)=">","Censure haute",IF(AC11="*****","Non testé","Normal")) -> Censure haute | AC11: >120 | AE11: =IF(ISBLANK(AF11),"",IF(LEFT(AF11,1)=">","Censure haute",IF(AF11="*****","Non testé","Normal"))) | AG11: =IF(ISBLANK(AF11),"",IFERROR(VALUE(AF11),"")) | AH11: Réactif | AI11: 1.132 | AJ11: 4.0134 | AL11: Réactif | AM11: 210 | AN11: 0 | AO11: =IF(ISBLANK(AM11),"",IF(AM11=92,IF(T11="Censure haute",120,""),IF(AB11="Censure haute",120,""))) -> 120
A12: US-530 | B12: Homme | C12: Non | D12: 20.1 | E12: Poids normal | F12: Non vacciné | I12: 15 | J12: S4 | K12: Négatif | L12: =IF(LEFT(M12,1)=">","Censure haute",IF(M12="*****","Non testé","Normal")) -> Normal | M12: 0.665 | N12: =IFERROR(VALUE(M12),"") -> 0.665 | O12: Négatif | P12: 0.048 | Q12: 1.1387 | S12: Réactif | T12: =IF(LEFT(U12,1)=">","Censure haute",IF(U12="*****","Echec technique","Normal")) -> Echec technique | U12: ***** | V12: =IFERROR(VALUE(U12),"") | W12: Non testé | X12: 0.033 | Y12: 0.9011 | AA12: Négatif | AB12: =IF(LEFT(AC12,1)=">","Censure haute",IF(AC12="*****","Non testé","Normal")) -> Censure haute | AC12: >120 | AE12: =IF(ISBLANK(AF12),"",IF(LEFT(AF12,1)=">","Censure haute",IF(AF12="*****","Non testé","Normal"))) | AG12: =IF(ISBLANK(AF12),"",IFERROR(VALUE(AF12),"")) | AH12: Réactif | AI12: 1.945 | AJ12: 0.6033 | AL12: Négatif | AM12: 210 | AN12: 0 | AO12: =IF(ISBLANK(AM12),"",IF(AM12=92,IF(T12="Censure haute",120,""),IF(AB12="Censure haute",120,""))) -> 120
A13: US-149 | B13: Homme | C13: Non | D13: 18.6 | E13: Poids normal | F13: Non vacciné | I13: 12 | J13: S1 | K13: Négatif | L13: =IF(LEFT(M13,1)=">","Censure haute",IF(M13="*****","Non testé","Normal")) -> Normal | M13: 0.365 | N13: =IFERROR(VALUE(M13),"") -> 0.365 | O13: Négatif | P13: 0.052 | Q13: 0.0831 | R13: 0.0814 | S13: Négatif | T13: =IF(LEFT(U13,1)=">","Censure haute",IF(U13="*****","Echec technique","Normal")) -> Censure haute | U13: >120 | V13: =IFERROR(VALUE(U13),"") | W13: Réactif | X13: 3.376 | Y13: 0.1192 | AA13: Négatif | AB13: =IF(LEFT(AC13,1)=">","Censure haute",IF(AC13="*****","Non testé","Normal")) -> Censure haute | AC13: >120 | AE13: =IF(ISBLANK(AF13),"",IF(LEFT(AF13,1)=">","Censure haute",IF(AF13="*****","Non testé","Normal"))) | AG13: =IF(ISBLANK(AF13),"",IFERROR(VALUE(AF13),"")) | AH13: Réactif | AI13: 2.346 | AJ13: 2.2869 | AL13: Réactif | AM13: 210 | AN13: 0 | AO13: =IF(ISBLANK(AM13),"",IF(AM13=92,IF(T13="Censure haute",120,""),IF(AB13="Censure haute",120,""))) -> 120
A14: US-433 | B14: Femme | C14: Oui | D14: 30.8 | E14: Obésité | F14: Non vacciné | I14: 15 | J14: S4 | K14: Négatif | L14: =IF(LEFT(M14,1)=">","Censure haute",IF(M14="*****","Non testé","Normal")) -> Normal | M14: 0.7767 | N14: =IFERROR(VALUE(M14),"") -> 0.7767 | O14: Négatif | P14: 0.053 | Q14: 0.537 | S14: Négatif | T14: =IF(LEFT(U14,1)=">","Censure haute",IF(U14="*****","Echec technique","Normal")) -> Censure haute | U14: >120 | V14: =IFERROR(VALUE(U14),"") | W14: Réactif | X14: 1.131 | Y14: 7.0446 | AA14: Négatif | AB14: =IF(LEFT(AC14,1)=">","Censure haute",IF(AC14="*****","Non testé","Normal")) -> Censure haute | AC14: >120 | AE14: =IF(ISBLANK(AF14),"",IF(LEFT(AF14,1)=">","Censure haute",IF(AF14="*****","Non testé","Normal"))) | AG14: =IF(ISBLANK(AF14),"",IFERROR(VALUE(AF14),"")) | AH14: Réactif | AI14: 0.732 | AJ14: 1.6983 | AL14: Réactif | AM14: 210 | AN14: 0 | AO14: =IF(ISBLANK(AM14),"",IF(AM14=92,IF(T14="Censure haute",120,""),IF(AB14="Censure haute",120,""))) -> 120
A15: US-258 | B15: Homme | C15: Non | D15: 17.8 | E15: Poids normal | F15: Non vacciné | I15: 12 | J15: S1 | K15: Négatif | L15: =IF(LEFT(M15,1)=">","Censure haute",IF(M15="*****","Non testé","Normal")) -> Normal | M15: 0.6755 | N15: =IFERROR(VALUE(M15),"") -> 0.6755 | O15: Négatif | P15: 0.056 | Q15: 0.1332 | S15: Négatif | T15: =IF(LEFT(U15,1)=">","Censure haute",IF(U15="*****","Echec technique","Normal")) -> Echec technique | U15: ***** | V15: =IFERROR(VALUE(U15),"") | W15: Non testé | X15: 0.905 | Y15: 2.6568 | AA15: Réactif | AB15: =IF(LEFT(AC15,1)=">","Censure haute",IF(AC15="*****","Non testé","Normal")) -> Non testé | AC15: ***** | AE15: =IF(ISBLANK(AF15),"",IF(LEFT(AF15,1)=">","Censure haute",IF(AF15="*****","Non testé","Normal"))) | AG15: =IF(ISBLANK(AF15),"",IFERROR(VALUE(AF15),"")) | AH15: Non testé | AI15: 3.5 | AJ15: 2.3841 | AL15: Réactif | AM15: 210 | AN15: 0 | AO15: =IF(ISBLANK(AM15),"",IF(AM15=92,IF(T15="Censure haute",120,""),IF(AB15="Censure haute",120,"")))
A16: US-124 | B16: Femme | C16: Non | D16: 16.8 | E16: Poids normal | F16: Non vacciné | I16: 15 | J16: S4 | K16: Négatif | L16: =IF(LEFT(M16,1)=">","Censure haute",IF(M16="*****","Non testé","Normal")) -> Normal | M16: 0.3431 | N16: =IFERROR(VALUE(M16),"") -> 0.3431 | O16: Négatif | P16: 0.057 | Q16: 0.3231 | S16: Négatif | T16: =IF(LEFT(U16,1)=">","Censure haute",IF(U16="*****","Echec technique","Normal")) -> Censure haute | U16: >120 | V16: =IFERROR(VALUE(U16),"") | W16: Réactif | X16: 0.041 | Y16: 5.6358 | AA16: Réactif | AB16: =IF(LEFT(AC16,1)=">","Censure haute",IF(AC16="*****","Non testé","Normal")) -> Censure haute | AC16: >120 | AE16: =IF(ISBLANK(AF16),"",IF(LEFT(AF16,1)=">","Censure haute",IF(AF16="*****","Non testé","Normal"))) | AG16: =IF(ISBLANK(AF16),"",IFERROR(VALUE(AF16),"")) | AH16: Réactif | AI16: 0.036 | AJ16: 3.0553 | AL16: Réactif | AM16: 210 | AN16: 0 | AO16: =IF(ISBLANK(AM16),"",IF(AM16=92,IF(T16="Censure haute",120,""),IF(AB16="Censure haute",120,""))) -> 120
A17: US-429 | B17: Femme | D17: 16.6 | E17: Poids normal | F17: Non vacciné | I17: 15 | J17: S4 | K17: Négatif | L17: =IF(LEFT(M17,1)=">","Censure haute",IF(M17="*****","Non testé","Normal")) -> Normal | M17: 1 | N17: =IFERROR(VALUE(M17),"") -> 1 | O17: Négatif | P17: 0.063 | Q17: 0.736 | S17: Négatif | T17: =IF(LEFT(U17,1)=">","Censure haute",IF(U17="*****","Echec technique","Normal")) -> Censure haute | U17: >120 | V17: =IFERROR(VALUE(U17),"") | W17: Réactif | X17: 0.868 | Y17: 0.3661 | AA17: Négatif | AB17: =IF(LEFT(AC17,1)=">","Censure haute",IF(AC17="*****","Non testé","Normal")) -> Censure haute | AC17: >120 | AE17: =IF(ISBLANK(AF17),"",IF(LEFT(AF17,1)=">","Censure haute",IF(AF17="*****","Non testé","Normal"))) | AG17: =IF(ISBLANK(AF17),"",IFERROR(VALUE(AF17),"")) | AH17: Réactif | AI17: 0.389 | AJ17: 3.9966 | AL17: Réactif | AM17: 210 | AN17: 0 | AO17: =IF(ISBLANK(AM17),"",IF(AM17=92,IF(T17="Censure haute",120,""),IF(AB17="Censure haute",120,""))) -> 120
A18: US-150 | B18: Femme | C18: Non | D18: 19.3 | E18: Poids normal | F18: Non vacciné | I18: 12 | J18: S1 | K18: Négatif | L18: =IF(LEFT(M18,1)=">","Censure haute",IF(M18="*****","Non testé","Normal")) -> Normal | M18: 0.4307 | N18: =IFERROR(VALUE(M18),"") -> 0.4307 | O18: Négatif | P18: 0.064 | Q18: 0.4397 | R18: 0.4511 | S18: Négatif | T18: =IF(LEFT(U18,1)=">","Censure haute",IF(U18="*****","Echec technique","Normal")) -> Censure haute | U18: >120 | V18: =IFERROR(VALUE(U18),"") | W18: Réactif | X18: 0.128 | Y18: 0.3466 | AA18: Négatif | AB18: =IF(LEFT(AC18,1)=">","Censure haute",IF(AC18="*****","Non testé","Normal")) -> Censure haute | AC18: >120 | AE18: =IF(ISBLANK(AF18),"",IF(LEFT(AF18,1)=">","Censure haute",IF(AF18="*****","Non testé","Normal"))) | AG18: =IF(ISBLANK(AF18),"",IFERROR(VALUE(AF18),"")) | AH18: Réactif | AI18: 0.146 | AJ18: 4.1619 | AL18: Réactif | AM18: 210 | AN18: 0 | AO18: =IF(ISBLANK(AM18),"",IF(AM18=92,IF(T18="Censure haute",120,""),IF(AB18="Censure haute",120,""))) -> 120
A19: US-493 | B19: Femme | D19: 21.2 | E19: Poids normal | F19: Non vacciné | I19: 12 | J19: S1 | K19: Négatif | L19: =IF(LEFT(M19,1)=">","Censure haute",IF(M19="*****","Non testé","Normal")) -> Normal | M19: 1.0447 | N19: =IFERROR(VALUE(M19),"") -> 1.0447 | O19: Négatif | P19: 0.065 | Q19: 2.6629 | S19: Réactif | T19: =IF(LEFT(U19,1)=">","Censure haute",IF(U19="*****","Echec technique","Normal")) -> Censure haute | U19: >120 | V19: =IFERROR(VALUE(U19),"") | W19: Réactif | X19: 0.26 | Y19: 5.6682 | AA19: Réactif | AB19: =IF(LEFT(AC19,1)=">","Censure haute",IF(AC19="*****","Non testé","Normal")) -> Censure haute | AC19: >120 | AE19: =IF(ISBLANK(AF19),"",IF(LEFT(AF19,1)=">","Censure haute",IF(AF19="*****","Non testé","Normal"))) | AG19: =IF(ISBLANK(AF19),"",IFERROR(VALUE(AF19),"")) | AH19: Réactif | AI19: 0.196 | AJ19: 3.5558 | AL19: Réactif | AM19: 210 | AN19: 0 | AO19: =IF(ISBLANK(AM19),"",IF(AM19=92,IF(T19="Censure haute",120,""),IF(AB19="Censure haute",120,""))) -> 120
A20: US-255 | B20: Homme | D20: 21.9 | E20: Surpoids | F20: Non vacciné | I20: 12 | J20: S1 | K20: Négatif | L20: =IF(LEFT(M20,1)=">","Censure haute",IF(M20="*****","Non testé","Normal")) -> Normal | M20: 0.8702 | N20: =IFERROR(VALUE(M20),"") -> 0.8702 | O20: Négatif | P20: 0.065 | Q20: 0.0699 | S20: Négatif | T20: =IF(LEFT(U20,1)=">","Censure haute",IF(U20="*****","Echec technique","Normal")) -> Normal | U20: 17.0308 | V20: =IFERROR(VALUE(U20),"") -> 17.0308 | W20: Réactif | X20: 0.606 | Y20: 0.9958 | AA20: Négatif | AB20: =IF(LEFT(AC20,1)=">","Censure haute",IF(AC20="*****","Non testé","Normal")) -> Non testé | AC20: ***** | AE20: =IF(ISBLANK(AF20),"",IF(LEFT(AF20,1)=">","Censure haute",IF(AF20="*****","Non testé","Normal"))) | AG20: =IF(ISBLANK(AF20),"",IFERROR(VALUE(AF20),"")) | AH20: Non testé | AI20: 0.506 | AJ20: 0.524 | AL20: Négatif | AM20: 92 | AN20: 1 | AO20: =IF(ISBLANK(AM20),"",IF(AM20=92,IF(T20="Censure haute",120,""),IF(AB20="Censure haute",120,"")))
A21: US-134 | B21: Femme | C21: Non | D21: 25.9 | E21: Surpoids | F21: Non vacciné | I21: 15 | J21: S4 | K21: Réactif | L21: =IF(LEFT(M21,1)=">","Censure haute",IF(M21="*****","Non testé","Normal")) -> Normal | M21: 0.5182 | N21: =IFERROR(VALUE(M21),"") -> 0.5182 | O21: Négatif | P21: 0.065 | Q21: 0.2593 | S21: Négatif | T21: =IF(LEFT(U21,1)=">","Censure haute",IF(U21="*****","Echec technique","Normal")) -> Censure haute | U21: >120 | V21: =IFERROR(VALUE(U21),"") | W21: Réactif | X21: 0.384 | Y21: 0.1082 | AA21: Négatif | AB21: =IF(LEFT(AC21,1)=">","Censure haute",IF(AC21="*****","Non testé","Normal")) -> Non testé | AC21: ***** | AE21: =IF(ISBLANK(AF21),"",IF(LEFT(AF21,1)=">","Censure haute",IF(AF21="*****","Non testé","Normal"))) | AG21: =IF(ISBLANK(AF21),"",IFERROR(VALUE(AF21),"")) | AH21: Non testé | AI21: 1.256 | AJ21: 3.0861 | AL21: Réactif | AM21: 210 | AN21: 0 | AO21: =IF(ISBLANK(AM21),"",IF(AM21=92,IF(T21="Censure haute",120,""),IF(AB21="Censure haute",120,"")))
A22: US-137 | B22: Femme | D22: 17.1 | E22: Poids normal | F22: Non vacciné | I22: 14 | J22: S4 | K22: Négatif | L22: =IF(LEFT(M22,1)=">","Censure haute",IF(M22="*****","Non testé","Normal")) -> Normal | M22: 0.6058 | N22: =IFERROR(VALUE(M22),"") -> 0.6058 | O22: Négatif | P22: 0.067 | Q22: 0.3978 | S22: Négatif | T22: =IF(LEFT(U22,1)=">","Censure haute",IF(U22="*****","Echec technique","Normal")) -> Censure haute | U22: >120 | V22: =IFERROR(VALUE(U22),"") | W22: Réactif | X22: 0.403 | Y22: 0.0861 | AA22: Négatif | AB22: =IF(LEFT(AC22,1)=">","Censure haute",IF(AC22="*****","Non testé","Normal")) -> Non testé | AC22: ***** | AE22: =IF(ISBLANK(AF22),"",IF(LEFT(AF22,1)=">","Censure haute",IF(AF22="*****","Non testé","Normal"))) | AG22: =IF(ISBLANK(AF22),"",IFERROR(VALUE(AF22),"")) | AH22: Non testé | AI22: 0.479 | AJ22: 1.9324 | AL22: Réactif | AM22: 210 | AN22: 0 | AO22: =IF(ISBLANK(AM22),"",IF(AM22=92,IF(T22="Censure haute",120,""),IF(AB22="Censure haute",120,"")))
A23: US-229 | B23: Femme | C23: Non | D23: 34.2 | E23: Obésité | F23: Non vacciné | I23: 11 | J23: S1 | K23: Négatif | L23: =IF(LEFT(M23,1)=">","Censure haute",IF(M23="*****","Non testé","Normal")) -> Normal | M23: 1.0216 | N23: =IFERROR(VALUE(M23),"") -> 1.0216 | O23: Négatif | P23: 0.072 | Q23: 0.1416 | S23: Négatif | T23: =IF(LEFT(U23,1)=">","Censure haute",IF(U23="*****","Echec technique","Normal")) -> Echec technique | U23: ***** | V23: =IFERROR(VALUE(U23),"") | W23: Non testé | X23: 0.745 | Y23: 1.7825 | AA23: Réactif | AB23: =IF(LEFT(AC23,1)=">","Censure haute",IF(AC23="*****","Non testé","Normal")) -> Non testé | AC23: ***** | AE23: =IF(ISBLANK(AF23),"",IF(LEFT(AF23,1)=">","Censure haute",IF(AF23="*****","Non testé","Normal"))) | AG23: =IF(ISBLANK(AF23),"",IFERROR(VALUE(AF23),"")) | AH23: Non testé | AI23: 2.678 | AJ23: 6.219 | AL23: Réactif | AM23: 210 | AN23: 0 | AO23: =IF(ISBLANK(AM23),"",IF(AM23=92,IF(T23="Censure haute",120,""),IF(AB23="Censure haute",120,"")))
A24: US-573 | B24: Femme | C24: Non | D24: 22.3 | E24: Surpoids | F24: Non vacciné | I24: 12 | J24: S1 | K24: Négatif | L24: =IF(LEFT(M24,1)=">","Censure haute",IF(M24="*****","Non testé","Normal")) -> Normal | M24: 0.9089 | N24: =IFERROR(VALUE(M24),"") -> 0.9089 | O24: Négatif | P24: 0.073 | Q24: 1.6025 | S24: Réactif | T24: =IF(LEFT(U24,1)=">","Censure haute",IF(U24="*****","Echec technique","Normal")) -> Censure haute | U24: >120 | V24: =IFERROR(VALUE(U24),"") | W24: Réactif | X24: 0.051 | Y24: 0.6138 | AA24: Négatif | AB24: =IF(LEFT(AC24,1)=">","Censure haute",IF(AC24="*****","Non testé","Normal")) -> Censure haute | AC24: >120 | AE24: =IF(ISBLANK(AF24),"",IF(LEFT(AF24,1)=">","Censure haute",IF(AF24="*****","Non testé","Normal"))) | AG24: =IF(ISBLANK(AF24),"",IFERROR(VALUE(AF24),"")) | AH24: Réactif | AI24: 0.073 | AJ24: 0.25 | AL24: Négatif | AM24: 210 | AN24: 0 | AO24: =IF(ISBLANK(AM24),"",IF(AM24=92,IF(T24="Censure haute",120,""),IF(AB24="Censure haute",120,""))) -> 120
A25: US-048 | B25: Homme | C25: Non | D25: 28.6 | E25: Obésité | F25: Non vacciné | I25: 15 | J25: S4 | K25: Négatif | L25: =IF(LEFT(M25,1)=">","Censure haute",IF(M25="*****","Non testé","Normal")) -> Normal | M25: 1.1533 | N25: =IFERROR(VALUE(M25),"") -> 1.1533 | O25: Négatif | P25: 0.074 | Q25: 0.4571 | S25: Négatif | T25: =IF(LEFT(U25,1)=">","Censure haute",IF(U25="*****","Echec technique","Normal")) -> Echec technique | U25: ***** | V25: =IFERROR(VALUE(U25),"") | W25: Non testé | X25: 0.077 | Y25: 1.479 | AA25: Réactif | AB25: =IF(LEFT(AC25,1)=">","Censure haute",IF(AC25="*****","Non testé","Normal")) -> Non testé | AC25: ***** | AE25: =IF(ISBLANK(AF25),"",IF(LEFT(AF25,1)=">","Censure haute",IF(AF25="*****","Non testé","Normal"))) | AG25: =IF(ISBLANK(AF25),"",IFERROR(VALUE(AF25),"")) | AH25: Non testé | AI25: 1.246 | AJ25: 1.2029 | AL25: Réactif | AM25: 210 | AN25: 0 | AO25: =IF(ISBLANK(AM25),"",IF(AM25=92,IF(T25="Censure haute",120,""),IF(AB25="Censure haute",120,"")))
A26: US-066 | B26: Femme | C26: Non | D26: 17.2 | E26: Poids normal | F26: Non vacciné | I26: 12 | J26: S1 | K26: Négatif | L26: =IF(LEFT(M26,1)=">","Censure haute",IF(M26="*****","Non testé","Normal")) -> Normal | M26: 1.1533 | N26: =IFERROR(VALUE(M26),"") -> 1.1533 | O26: Négatif | P26: 0.089 | Q26: 0.2923 | S26: Négatif | T26: =IF(LEFT(U26,1)=">","Censure haute",IF(U26="*****","Echec technique","Normal")) -> Echec technique | U26: ***** | V26: =IFERROR(VALUE(U26),"") | W26: Non testé | X26: 0.684 | Y26: 3.0044 | AA26: Réactif | AB26: =IF(LEFT(AC26,1)=">","Censure haute",IF(AC26="*****","Non testé","Normal")) -> Non testé | AC26: ***** | AE26: =IF(ISBLANK(AF26),"",IF(LEFT(AF26,1)=">","Censure haute",IF(AF26="*****","Non testé","Normal"))) | AG26: =IF(ISBLANK(AF26),"",IFERROR(VALUE(AF26),"")) | AH26: Non testé | AI26: 0.365 | AJ26: 1.3504 | AL26: Réactif | AM26: 210 | AN26: 0 | AO26: =IF(ISBLANK(AM26),"",IF(AM26=92,IF(T26="Censure haute",120,""),IF(AB26="Censure haute",120,"")))
A27: US-169 | B27: Femme | C27: Non | D27: 27.2 | E27: Surpoids | F27: Non vacciné | I27: 15 | J27: S4 | K27: Réactif | L27: =IF(LEFT(M27,1)=">","Censure haute",IF(M27="*****","Non testé","Normal")) -> Normal | M27: 1.3894 | N27: =IFERROR(VALUE(M27),"") -> 1.3894 | O27: Négatif | P27: 0.089 | Q27: 0.0586 | S27: Négatif | T27: =IF(LEFT(U27,1)=">","Censure haute",IF(U27="*****","Echec technique","Normal")) -> Censure haute | U27: >120 | V27: =IFERROR(VALUE(U27),"") | W27: Réactif | X27: 3.5 | Y27: 5.0045 | AA27: Réactif | AB27: =IF(LEFT(AC27,1)=">","Censure haute",IF(AC27="*****","Non testé","Normal")) -> Normal | AC27: 600531 | AD27: 60.0531 | AE27: =IF(ISBLANK(AF27),"",IF(LEFT(AF27,1)=">","Censure haute",IF(AF27="*****","Non testé","Normal"))) | AG27: =IF(ISBLANK(AF27),"",IFERROR(VALUE(AF27),"")) | AH27: Réactif | AI27: 2.813 | AJ27: 1.8802 | AL27: Réactif | AO27: =IF(ISBLANK(AM27),"",IF(AM27=92,IF(T27="Censure haute",120,""),IF(AB27="Censure haute",120,"")))
A28: US-512 | B28: Homme | D28: 16.4 | E28: Poids normal | F28: Non vacciné | I28: 12 | J28: S1 | K28: Réactif | L28: =IF(LEFT(M28,1)=">","Censure haute",IF(M28="*****","Non testé","Normal")) -> Normal | M28: 1.8263 | N28: =IFERROR(VALUE(M28),"") -> 1.8263 | O28: Négatif | P28: 0.1 | Q28: 3.059 | S28: Réactif | T28: =IF(LEFT(U28,1)=">","Censure haute",IF(U28="*****","Echec technique","Normal")) -> Normal | U28: 45.4201 | V28: =IFERROR(VALUE(U28),"") -> 45.4201 | W28: Réactif | X28: 0.207 | Y28: 1.6463 | AA28: Réactif | AB28: =IF(LEFT(AC28,1)=">","Censure haute",IF(AC28="*****","Non testé","Normal")) -> Normal | AC28: 979592 | AD28: 97.9592 | AE28: =IF(ISBLANK(AF28),"",IF(LEFT(AF28,1)=">","Censure haute",IF(AF28="*****","Non testé","Normal"))) | AG28: =IF(ISBLANK(AF28),"",IFERROR(VALUE(AF28),"")) | AH28: Réactif | AI28: 0.218 | AJ28: 5.7516 | AL28: Réactif | AO28: =IF(ISBLANK(AM28),"",IF(AM28=92,IF(T28="Censure haute",120,""),IF(AB28="Censure haute",120,"")))
